Workbook

Sheet EINDTABEL 1 met formule
A1: SBI-CODE | B1: SBI-CODE 2008 | D1: OMSCHRIJVING | E1: AFSTANDEN IN METERS
C2: nummer | E2: GEUR | F2: STOF | G2: GELUID | J2: GEVAAR | L2: VERKEER | O2: GROOTSTE AFSTAND | P2: CAT | R2: CATEGORIE | X2: NIEUW
A3: 15 | B3: 10, 11 | C3: - | D3: VERVAARDIGING VAN VOEDINGSMIDDELEN EN DRANKEN | P3: =VLOOKUP($O3,codetabel!$A$1:$B$12,2,FALSE) -> #N/A | R3: =IF(ISNA(P3),"",P3)
A4: 151 | B4: 101, 102 | C4: 0 | D4: Slachterijen en overige vleesverwerking: | P4: =VLOOKUP($O4,codetabel!$A$1:$B$12,2,FALSE) -> #N/A | R4: =IF(ISNA(P4),"",P4)
A5: 151 | B5: 101, 102 | C5: 1 | D5: - slachterijen en pluimveeslachterijen | E5: 100 | F5: 0 | G5: 100 | H5: C | J5: 50 | K5: R | L5: 2 | M5: G | O5: =MAX(J5,G5,F5,E5) -> 100 | P5: =VLOOKUP($O5,codetabel!$A$1:$B$12,2,FALSE) -> 3.2 | Q5: D | R5: =IF(ISNA(P5),"",P5) -> 3.2
A6: 151 | B6: 101 | C6: 3 | D6: - bewerkingsinrichting van darmen en vleesafval | E6: 300 | F6: 0 | G6: 100 | H6: C | J6: 50 | K6: R | L6: 2 | M6: G | O6: =MAX(J6,G6,F6,E6) -> 300 | P6: =VLOOKUP($O6,codetabel!$A$1:$B$12,2,FALSE) -> 4.2 | R6: =IF(ISNA(P6),"",P6) -> 4.2
A7: 151 | B7: 101 | C7: 4 | D7: - vleeswaren- en vleesconservenfabrieken: p.o. > 1000 m² | E7: 100 | F7: 0 | G7: 100 | H7: C | J7: 50 | K7: R | L7: 2 | M7: G | O7: =MAX(J7,G7,F7,E7) -> 100 | P7: =VLOOKUP($O7,codetabel!$A$1:$B$12,2,FALSE) -> 3.2 | R7: =IF(ISNA(P7),"",P7) -> 3.2
A8: 151 | B8: 101 | C8: 5 | D8: - vleeswaren- en vleesconservenfabrieken: p.o. <= 1000 m² | E8: 50 | F8: 0 | G8: 50 | H8: C | J8: 30 | L8: 1 | M8: G | O8: =MAX(J8,G8,F8,E8) -> 50 | P8: =VLOOKUP($O8,codetabel!$A$1:$B$12,2,FALSE) -> 3.1 | R8: =IF(ISNA(P8),"",P8) -> 3.1 | X8: X
A9: 151 | B9: 101 | C9: 6 | D9: - vleeswaren- en vleesconservenfabrieken: p.o. <= 200 m² | E9: 30 | F9: 0 | G9: 50 | J9: 10 | L9: 1 | M9: G | O9: =MAX(J9,G9,F9,E9) -> 50 | P9: =VLOOKUP($O9,codetabel!$A$1:$B$12,2,FALSE) -> 3.1 | R9: =IF(ISNA(P9),"",P9) -> 3.1 | X9: X
A10: 151 | B10: 101, 102 | C10: 7 | D10: - loonslachterijen | E10: 50 | F10: 0 | G10: 50 | J10: 10 | L10: 1 | M10: G | O10: =MAX(J10,G10,F10,E10) -> 50 | P10: =VLOOKUP($O10,codetabel!$A$1:$B$12,2,FALSE) -> 3.1 | R10: =IF(ISNA(P10),"",P10) -> 3.1
A11: 151 | B11: 108 | C11: 8 | D11: - vervaardiging van snacks en vervaardiging van kant-en-klaar-maaltijden met p.o. < 2.000 m² | E11: 50 | F11: 0 | G11: 50 | J11: 10 | L11: 2 | M11: G | O11: =MAX(J11,G11,F11,E11) -> 50 | P11: =VLOOKUP($O11,codetabel!$A$1:$B$12,2,FALSE) -> 3.1 | R11: =IF(ISNA(P11),"",P11) -> 3.1 | X11: X
A12: 152 | B12: 102 | C12: 0 | D12: Visverwerkingsbedrijven: | P12: =VLOOKUP($O12,codetabel!$A$1:$B$12,2,FALSE) -> #N/A | R12: =IF(ISNA(P12),"",P12)
A13: 152 | B13: 102 | C13: 2 | D13: - conserveren | E13: 200 | F13: 0 | G13: 100 | H13: C | J13: 30 | L13: 2 | M13: G | O13: =MAX(J13,G13,F13,E13) -> 200 | P13: =VLOOKUP($O13,codetabel!$A$1:$B$12,2,FALSE) -> 4.1 | R13: =IF(ISNA(P13),"",P13) -> 4.1
A14: 152 | B14: 102 | C14: 3 | D14: - roken | E14: 300 | F14: 0 | G14: 50 | H14: C | J14: 0 | L14: 1 | M14: G | O14: =MAX(J14,G14,F14,E14) -> 300 | P14: =VLOOKUP($O14,codetabel!$A$1:$B$12,2,FALSE) -> 4.2 | R14: =IF(ISNA(P14),"",P14) -> 4.2
A15: 152 | B15: 102 | C15: 4 | D15: - verwerken anderszins: p.o.> 1000 m² | E15: 300 | F15: 10 | G15: 50 | H15: C | J15: 30 | L15: 2 | M15: G | O15: =MAX(J15,G15,F15,E15) -> 300 | P15: =VLOOKUP($O15,codetabel!$A$1:$B$12,2,FALSE) -> 4.2 | Q15: D | R15: =IF(ISNA(P15),"",P15) -> 4.2
A16: 152 | B16: 102 | C16: 5 | D16: - verwerken anderszins: p.o. <= 1000 m² | E16: 100 | F16: 10 | G16: 50 | J16: 30 | L16: 1 | M16: G | O16: =MAX(J16,G16,F16,E16) -> 100 | P16: =VLOOKUP($O16,codetabel!$A$1:$B$12,2,FALSE) -> 3.2 | R16: =IF(ISNA(P16),"",P16) -> 3.2 | X16: X
A17: 152 | B17: 102 | C17: 6 | D17: - verwerken anderszins: p.o. <= 300 m² | E17: 50 | F17: 10 | G17: 30 | J17: 10 | L17: 1 | M17: G | O17: =MAX(J17,G17,F17,E17) -> 50 | P17: =VLOOKUP($O17,codetabel!$A$1:$B$12,2,FALSE) -> 3.1 | R17: =IF(ISNA(P17),"",P17) -> 3.1 | X17: X
A18: 1531 | B18: 1031 | C18: 0 | D18: Aardappelprodukten fabrieken: | P18: =VLOOKUP($O18,codetabel!$A$1:$B$12,2,FALSE) -> #N/A | R18: =IF(ISNA(P18),"",P18)
A19: 1531 | B19: 1031 | C19: 1 | D19: - vervaardiging van aardappelproducten | E19: 300 | F19: 30 | G19: 200 | H19: C | J19: 50 | K19: R | L19: 2 | M19: G | O19: =MAX(J19,G19,F19,E19) -> 300 | P19: =VLOOKUP($O19,codetabel!$A$1:$B$12,2,FALSE) -> 4.2 | R19: =IF(ISNA(P19),"",P19) -> 4.2 | X19: X
A20: 1531 | B20: 1031 | C20: 2 | D20: - vervaardiging van snacks met p.o. < 2.000 m² | E20: 50 | F20: 10 | G20: 50 | J20: 50 | K20: R | L20: 1 | M20: G | O20: =MAX(J20,G20,F20,E20) -> 50 | P20: =VLOOKUP($O20,codetabel!$A$1:$B$12,2,FALSE) -> 3.1 | R20: =IF(ISNA(P20),"",P20) -> 3.1 | X20: X
A21: 1532, 1533 | B21: 1032, 1039 | C21: 0 | D21: Groente- en fruitconservenfabrieken: | P21: =VLOOKUP($O21,codetabel!$A$1:$B$12,2,FALSE) -> #N/A | R21: =IF(ISNA(P21),"",P21)
A22: 1532, 1533 | B22: 1032, 1039 | C22: 1 | D22: - jam | E22: 50 | F22: 10 | G22: 100 | H22: C | J22: 10 | L22: 1 | M22: G | O22: =MAX(J22,G22,F22,E22) -> 100 | P22: =VLOOKUP($O22,codetabel!$A$1:$B$12,2,FALSE) -> 3.2 | R22: =IF(ISNA(P22),"",P22) -> 3.2
A23: 1532, 1533 | B23: 1032, 1039 | C23: 2 | D23: - groente algemeen | E23: 50 | F23: 10 | G23: 100 | H23: C | J23: 10 | L23: 2 | M23: G | O23: =MAX(J23,G23,F23,E23) -> 100 | P23: =VLOOKUP($O23,codetabel!$A$1:$B$12,2,FALSE) -> 3.2 | R23: =IF(ISNA(P23),"",P23) -> 3.2
A24: 1532, 1533 | B24: 1032, 1039 | C24: 3 | D24: - met koolsoorten | E24: 100 | F24: 10 | G24: 100 | H24: C | J24: 10 | L24: 2 | M24: G | O24: =MAX(J24,G24,F24,E24) -> 100 | P24: =VLOOKUP($O24,codetabel!$A$1:$B$12,2,FALSE) -> 3.2 | R24: =IF(ISNA(P24),"",P24) -> 3.2
A25: 1532, 1533 | B25: 1032, 1039 | C25: 4 | D25: - met drogerijen | E25: 300 | F25: 10 | G25: 200 | H25: C | J25: 30 | L25: 2 | M25: G | O25: =MAX(J25,G25,F25,E25) -> 300 | P25: =VLOOKUP($O25,codetabel!$A$1:$B$12,2,FALSE) -> 4.2 | R25: =IF(ISNA(P25),"",P25) -> 4.2
A26: 1532, 1533 | B26: 1032, 1039 | C26: 5 | D26: - met uienconservering (zoutinleggerij) | E26: 300 | F26: 10 | G26: 100 | H26: C | J26: 10 | L26: 2 | M26: G | O26: =MAX(J26,G26,F26,E26) -> 300 | P26: =VLOOKUP($O26,codetabel!$A$1:$B$12,2,FALSE) -> 4.2 | R26: =IF(ISNA(P26),"",P26) -> 4.2
A27: 1541 | B27: 104101 | C27: 0 | D27: Vervaardiging van ruwe plantaardige en dierlijke oliën en vetten: | P27: =VLOOKUP($O27,codetabel!$A$1:$B$12,2,FALSE) -> #N/A | R27: =IF(ISNA(P27),"",P27)
A28: 1541 | B28: 104101 | C28: 1 | D28: - p.c. < 250.000 t/j | E28: 200 | F28: 30 | G28: 100 | H28: C | J28: 30 | K28: R | L28: 3 | M28: G | O28: =MAX(J28,G28,F28,E28) -> 200 | P28: =VLOOKUP($O28,codetabel!$A$1:$B$12,2,FALSE) -> 4.1 | R28: =IF(ISNA(P28),"",P28) -> 4.1
A29: 1541 | B29: 104101 | C29: 2 | D29: - p.c. >= 250.000 t/j | E29: 300 | F29: 50 | G29: 300 | H29: C | I29: Z | J29: 50 | K29: R | L29: 3 | M29: G | O29: =MAX(J29,G29,F29,E29) -> 300 | P29: =VLOOKUP($O29,codetabel!$A$1:$B$12,2,FALSE) -> 4.2 | R29: =IF(ISNA(P29),"",P29) -> 4.2
A30: 1542 | B30: 104102 | C30: 0 | D30: Raffinage van plantaardige en dierlijke oliën en vetten: | P30: =VLOOKUP($O30,codetabel!$A$1:$B$12,2,FALSE) -> #N/A | R30: =IF(ISNA(P30),"",P30)
A31: 1542 | B31: 104102 | C31: 1 | D31: - p.c. < 250.000 t/j | E31: 200 | F31: 10 | G31: 100 | H31: C | J31: 100 | K31: R | L31: 3 | M31: G | O31: =MAX(J31,G31,F31,E31) -> 200 | P31: =VLOOKUP($O31,codetabel!$A$1:$B$12,2,FALSE) -> 4.1 | R31: =IF(ISNA(P31),"",P31) -> 4.1
A32: 1542 | B32: 104102 | C32: 2 | D32: - p.c. >= 250.000 t/j | E32: 300 | F32: 10 | G32: 300 | H32: C | I32: Z | J32: 200 | K32: R | L32: 3 | M32: G | O32: =MAX(J32,G32,F32,E32) -> 300 | P32: =VLOOKUP($O32,codetabel!$A$1:$B$12,2,FALSE) -> 4.2 | R32: =IF(ISNA(P32),"",P32) -> 4.2
A33: 1543 | B33: 1042 | C33: 0 | D33: Margarinefabrieken: | P33: =VLOOKUP($O33,codetabel!$A$1:$B$12,2,FALSE) -> #N/A | R33: =IF(ISNA(P33),"",P33)
A34: 1543 | B34: 1042 | C34: 1 | D34: - p.c. < 250.000 t/j | E34: 100 | F34: 10 | G34: 200 | H34: C | J34: 30 | K34: R | L34: 3 | M34: G | O34: =MAX(J34,G34,F34,E34) -> 200 | P34: =VLOOKUP($O34,codetabel!$A$1:$B$12,2,FALSE) -> 4.1 | R34: =IF(ISNA(P34),"",P34) -> 4.1
A35: 1543 | B35: 1042 | C35: 2 | D35: - p.c. >= 250.000 t/j | E35: 200 | F35: 10 | G35: 300 | H35: C | I35: Z | J35: 50 | K35: R | L35: 3 | M35: G | O35: =MAX(J35,G35,F35,E35) -> 300 | P35: =VLOOKUP($O35,codetabel!$A$1:$B$12,2,FALSE) -> 4.2 | R35: =IF(ISNA(P35),"",P35) -> 4.2
A36: 1551 | B36: 1052 | C36: 0 | D36: Zuivelprodukten fabrieken: | P36: =VLOOKUP($O36,codetabel!$A$1:$B$12,2,FALSE) -> #N/A | R36: =IF(ISNA(P36),"",P36)
A37: 1551 | B37: 1051 | C37: 3 | D37: - melkprodukten fabrieken v.c. < 55.000 t/j | E37: 50 | F37: 0 | G37: 100 | H37: C | J37: 50 | K37: R | L37: 2 | M37: G | O37: =MAX(J37,G37,F37,E37) -> 100 | P37: =VLOOKUP($O37,codetabel!$A$1:$B$12,2,FALSE) -> 3.2 | R37: =IF(ISNA(P37),"",P37) -> 3.2
A38: 1551 | B38: 1051 | C38: 4 | D38: - melkprodukten fabrieken v.c. >= 55.000 t/j | E38: 100 | F38: 0 | G38: 300 | H38: C | I38: Z | J38: 50 | K38: R | L38: 3 | M38: G | O38: =MAX(J38,G38,F38,E38) -> 300 | P38: =VLOOKUP($O38,codetabel!$A$1:$B$12,2,FALSE) -> 4.2 | R38: =IF(ISNA(P38),"",P38) -> 4.2
A39: 1551 | B39: 1051 | C39: 5 | D39: - overige zuivelprodukten fabrieken | E39: 50 | F39: 50 | G39: 300 | H39: C | J39: 50 | K39: R | L39: 3 | M39: G | O39: =MAX(J39,G39,F39,E39) -> 300 | P39: =VLOOKUP($O39,codetabel!$A$1:$B$12,2,FALSE) -> 4.2 | R39: =IF(ISNA(P39),"",P39) -> 4.2
A40: 1552 | B40: 1052 | C40: 1 | D40: Consumptie-ijsfabrieken: p.o. > 200 m² | E40: 50 | F40: 0 | G40: 100 | H40: C | J40: 50 | K40: R | L40: 2 | M40: G | O40: =MAX(J40,G40,F40,E40) -> 100 | P40: =VLOOKUP($O40,codetabel!$A$1:$B$12,2,FALSE) -> 3.2 | R40: =IF(ISNA(P40),"",P40) -> 3.2
...

Sheet codetabel
A1: afstabnd | B1: code
A3: 10 | B3: 1
A4: 30 | B4: 2
A5: 50 | B5: 3.1
A6: 100 | B6: 3.2
A7: 200 | B7: 4.1
A8: 300 | B8: 4.2
A9: 500 | B9: 5.1
A10: 700 | B10: 5.2
A11: 1000 | B11: 5.3
A12: 1500 | B12: 6
