Workbook

Sheet README
A1: Odour distance (geur) vs. environmental category - analysis workbook
A2: Generated by analysis/build_analysis.py; method in analysis/METHODOLOGY.md, results in analysis/FINDINGS.md.
A3: Source files in doc/ are read only; their SHA-256 hashes are listed on 'Statistics' and are checked before and after the build.
A5: Sheets
A6: Statistics - correlation coefficients (formula and Python, cross-checked) and source verification summary.
A7: Figure - correlation diagrams, also in analysis/figures/: count heatmaps (geur on x, then axes reversed) and bubble diagrams with regression line (geur on x, then axes reversed).
A8: Regression - slope, intercept and R2 of the regression lines in the bubble diagrams (formula and Python, cross-checked).
A9: Data_B1, Data_B2, Data_B1_union_B2 - FINAL datasets: values only, one row per activity with a numeric geur distance and a category. Columns N-R are rank formulas used by 'Statistics'; S-T are step indices used by 'Regression'.
A10: B1_extract, B2_extract - INTERMEDIATE: every non-empty source row with raw values, the original formula/content of O and R, the cached (displayed) values, and recalculation checks.
A11: Codetabel - distance-to-category lookup with ordinal ranks.
A12: Crosstab_B1, Crosstab_B2 - frequency tables (COUNTIFS) behind the figure.
A14: Colour conventions
... A21: Bijlage 1 rows 763-837 are, according to the owner of the file, a targeted cut-and-paste of columns E and R from an updated version of bijlage 1 that was published on the VNG website for the former guideline and can no longer be found. They carry only a geur value and a hardcoded category, without activity description or other distances, cannot be linked to an activity and are therefore excluded. Rows with numeric geur and category: n = 47, Spearman rho = 0.334 (p = 0.022). Bijlage 1 including these rows: n = 606, Spearman rho = 0.610.

Sheet Statistics
A1: Rank correlation between geur distance and environmental category
A2: Black = live formula on the dataset sheets (re-computes in Excel/LibreOffice). Blue = value computed by build_analysis.py (scipy 'spearmanr', 'kendalltau' variant b, 'pearsonr'; 2000-sample percentile bootstrap, seed 1).
A4: # | B4: Analysis | C4: Dataset sheet | D4: n (formula) | E4: Spearman rho (formula) | F4: Spearman rho (Python) | G4: Check | H4: Spearman 95% CI (bootstrap) | I4: p (Spearman) | J4: Kendall tau-b (Python) | K4: p (Kendall) | L4: Pearson r geur m vs rank (formula) | M4: Pearson r (Python) | N4: p (Pearson) | O4: Spearman rho from max() construction alone (permutation mean, 95% range)
A5: 1 | B5: Bijlage 1: geur vs category (all activities) | C5: Data_B1 | D5: =COUNT(Data_B1!N2:N560) -> 559 | E5: =CORREL(Data_B1!N2:N560,Data_B1!O2:O560) -> 0.6176542 | F5: 0.617654 | G5: =IF(ABS(E5-F5)<0.0001,"OK","MISMATCH") -> OK | H5: 0.553 to 0.675 | I5: 4.22e-60 | J5: 0.51714 | K5: 1.53e-58 | L5: =CORREL(Data_B1!F2:F560,Data_B1!H2:H560) -> 0.51068639 | M5: 0.510686 | N5: 1.86e-38 | O5: 0.393 (0.334 to 0.447)
A6: 2 | B6: Bijlage 1: geur vs category, only activities where geur is NOT decisive | C6: Data_B1 | D6: =COUNT(Data_B1!P2:P560) -> 379 | E6: =CORREL(Data_B1!P2:P560,Data_B1!Q2:Q560) -> 0.63975209 | F6: 0.639752 | G6: =IF(ABS(E6-F6)<0.0001,"OK","MISMATCH") -> OK | H6: 0.572 to 0.707 | I6: 5.14e-45 | J6: 0.536668 | K6: 2.88e-41 | L6: n/a (subset) | M6: 0.51 | N6: 1.74e-26 | O6: n/a
A7: 3 | B7: Bijlage 1: geur vs category based on stof/geluid/gevaar only (geur removed) | C7: Data_B1 | D7: =COUNT(Data_B1!N2:N560) -> 559 | E7: =CORREL(Data_B1!N2:N560,Data_B1!R2:R560) -> 0.47371633 | F7: 0.473716 | G7: =IF(ABS(E7-F7)<0.0001,"OK","MISMATCH") -> OK | H7: 0.404 to 0.540 | I7: 1.3e-32 | J7: 0.373187 | K7: 4.1e-31 | L7: =CORREL(Data_B1!F2:F560,Data_B1!L2:L560) -> 0.36283393 | M7: 0.362834 | N7: 7.78e-19 | O7: n/a
A8: 4 | B8: Bijlage 2: geur vs category (all activities) | C8: Data_B2 | D8: =COUNT(Data_B2!N2:N316) -> 315 | E8: =CORREL(Data_B2!N2:N316,Data_B2!O2:O316) -> 0.61000399 | F8: 0.610004 | G8: =IF(ABS(E8-F8)<0.0001,"OK","MISMATCH") -> OK | H8: 0.521 to 0.692 | I8: 1.72e-33 | J8: 0.528913 | K8: 4.1e-33 | L8: =CORREL(Data_B2!F2:F316,Data_B2!H2:H316) -> 0.59744957 | M8: 0.59745 | N8: 7.34e-32 | O8: 0.459 (0.391 to 0.528)
A9: 5 | B9: Bijlage 2: geur vs category, only activities where geur is NOT decisive | C9: Data_B2 | D9: =COUNT(Data_B2!P2:P316) -> 198 | E9: =CORREL(Data_B2!P2:P316,Data_B2!Q2:Q316) -> 0.56115997 | F9: 0.56116 | G9: =IF(ABS(E9-F9)<0.0001,"OK","MISMATCH") -> OK | H9: 0.440 to 0.665 | I9: 8.04e-18 | J9: 0.487131 | K9: 1.31e-17 | L9: n/a (subset) | M9: 0.461801 | N9: 7.49e-12 | O9: n/a
A10: 6 | B10: Bijlage 2: geur vs category based on stof/geluid/gevaar only (geur removed) | C10: Data_B2 | D10: =COUNT(Data_B2!N2:N316) -> 315 | E10: =CORREL(Data_B2!N2:N316,Data_B2!R2:R316) -> 0.38532041 | F10: 0.38532 | G10: =IF(ABS(E10-F10)<0.0001,"OK","MISMATCH") -> OK | H10: 0.287 to 0.484 | I10: 1.37e-12 | J10: 0.310735 | K10: 1.73e-12 | L10: =CORREL(Data_B2!F2:F316,Data_B2!L2:L316) -> 0.45384047 | M10: 0.45384 | N10: 2.07e-17 | O10: n/a
A11: 7 | B11: Union B1 + B2 (duplicates removed): geur vs category | C11: Data_B1_union_B2 | D11: =COUNT(Data_B1_union_B2!N2:N563) -> 562 | E11: =CORREL(Data_B1_union_B2!N2:N563,Data_B1_union_B2!O2:O563) -> 0.61756168 | F11: 0.617562 | G11: =IF(ABS(E11-F11)<0.0001,"OK","MISMATCH") -> OK | H11: 0.556 to 0.675 | I11: 2.16e-60 | J11: 0.51727 | K11: 7.53e-59 | L11: =CORREL(Data_B1_union_B2!F2:F563,Data_B1_union_B2!H2:H563) -> 0.5110654 | M11: 0.511065 | N11: 1.02e-38 | O11: 0.394 (0.331 to 0.451)
A13: Verification of source values
A14: Source | B14: Rows extracted | C14: Rows included | D14: O cached = recalculated (formula) | E14: R cached = recalculated (formula) | F14: R hardcoded (not formula) among included | G14: Geur decisive among included | H14: SHA-256 source file (unchanged)
A15: B1 | B15: =COUNTA(B1_extract!A2:A825) -> 824 | C15: =COUNTIF(B1_extract!X2:X825,TRUE()) -> 559 | D15: =COUNTIFS(B1_extract!X2:X825,TRUE(),B1_extract!U2:U825,"OK")&" of "&C15 -> 559 of 559 | E15: =COUNTIFS(B1_extract!X2:X825,TRUE(),B1_extract!V2:V825,"OK")&" of "&C15 -> 559 of 559 | F15: =COUNTIFS(B1_extract!X2:X825,TRUE(),B1_extract!N2:N825,FALSE()) -> 15 | G15: =COUNTIF(B1_extract!Z2:Z825,TRUE()) -> 180 | H15: f1e7f50be69da4b1f18f5afe682ab090e96817f9c82fec1d989237359ef0e16d
A16: B2 | B16: =COUNTA(B2_extract!A2:A468) -> 467 | C16: =COUNTIF(B2_extract!X2:X468,TRUE()) -> 315 | D16: =COUNTIFS(B2_extract!X2:X468,TRUE(),B2_extract!U2:U468,"OK")&" of "&C16 -> 315 of 315 | E16: =COUNTIFS(B2_extract!X2:X468,TRUE(),B2_extract!V2:V468,"OK")&" of "&C16 -> 315 of 315 | F16: =COUNTIFS(B2_extract!X2:X468,TRUE(),B2_extract!N2:N468,FALSE()) -> 7 | G16: =COUNTIF(B2_extract!Z2:Z468,TRUE()) -> 117 | H16: e5be457a851190acf6f678d492c0ad2fa92dc298c18b001930bce9ff16e2ee48

Sheet Figure

Sheet Regression
A1: Regression lines in the bubble diagrams (OLS on step positions)
A2: x and y are step positions, not metres: geur 0, 10, 30, ... 1500 m = steps 0-10; category 1 ... 6 = steps 0-9 (columns S and T on the dataset sheets). Black = live formula (SLOPE/INTERCEPT/RSQ); blue = scipy.stats.linregress.
A4: Dataset | B4: x | C4: y | D4: n | E4: Slope (formula) | F4: Intercept (formula) | G4: R² (formula) | H4: Slope (Python) | I4: Intercept (Python) | J4: R² (Python) | K4: SE slope (Python) | L4: p slope (Python) | M4: Check
A5: B1 | B5: geur step | C5: category step | D5: =COUNT(Data_B1!S2:S560) -> 559 | E5: =SLOPE(Data_B1!T2:T560,Data_B1!S2:S560) -> 0.604857 | F5: =INTERCEPT(Data_B1!T2:T560,Data_B1!S2:S560) -> 1.8182053 | G5: =RSQ(Data_B1!T2:T560,Data_B1!S2:S560) -> 0.35509145 | H5: 0.604857 | I5: 1.818205 | J5: 0.355091 | K5: 0.034539 | L5: 4.98e-55 | M5: =IF(AND(ABS(E5-H5)<0.0001,ABS(F5-I5)<0.0001),"OK","MISMATCH") -> OK
A6: B1 | B6: category step | C6: geur step | D6: =COUNT(Data_B1!T2:T560) -> 559 | E6: =SLOPE(Data_B1!S2:S560,Data_B1!T2:T560) -> 0.58706677 | F6: =INTERCEPT(Data_B1!S2:S560,Data_B1!T2:T560) -> 0.60081707 | G6: =RSQ(Data_B1!S2:S560,Data_B1!T2:T560) -> 0.35509145 | H6: 0.587067 | I6: 0.600817 | J6: 0.355091 | K6: 0.033523 | L6: 4.98e-55 | M6: =IF(AND(ABS(E6-H6)<0.0001,ABS(F6-I6)<0.0001),"OK","MISMATCH") -> OK
A7: B2 | B7: geur step | C7: category step | D7: =COUNT(Data_B2!S2:S316) -> 315 | E7: =SLOPE(Data_B2!T2:T316,Data_B2!S2:S316) -> 0.47047348 | F7: =INTERCEPT(Data_B2!T2:T316,Data_B2!S2:S316) -> 1.9814681 | G7: =RSQ(Data_B2!T2:T316,Data_B2!S2:S316) -> 0.36841179 | H7: 0.470473 | I7: 1.981468 | J7: 0.368412 | K7: 0.034819 | L7: 4.33e-33 | M7: =IF(AND(ABS(E7-H7)<0.0001,ABS(F7-I7)<0.0001),"OK","MISMATCH") -> OK
A8: B2 | B8: category step | C8: geur step | D8: =COUNT(Data_B2!T2:T316) -> 315 | E8: =SLOPE(Data_B2!S2:S316,Data_B2!T2:T316) -> 0.78306602 | F8: =INTERCEPT(Data_B2!S2:S316,Data_B2!T2:T316) -> 0.25893253 | G8: =RSQ(Data_B2!S2:S316,Data_B2!T2:T316) -> 0.36841179 | H8: 0.783066 | I8: 0.258933 | J8: 0.368412 | K8: 0.057953 | L8: 4.33e-33 | M8: =IF(AND(ABS(E8-H8)<0.0001,ABS(F8-I8)<0.0001),"OK","MISMATCH") -> OK

Sheet Data_B1
A1: Source | B1: Source row | C1: SBI (old) | D1: SBI-2008 | E1: Omschrijving | F1: Geur (m) | G1: Categorie | H1: Category rank | I1: Max distance (m) | J1: Geur decisive | K1: Max other distances (m) | L1: Category rank excl. geur | M1: In both B1 and B2 | N1: Midrank geur | O1: Midrank category | P1: Midrank geur (not decisive) | Q1: Midrank category (not decisive) | R1: Midrank category excl. geur | S1: Geur step index (0-10) | T1: Category step index (0-9)
A2: B1 | B2: 4 | C2: 0111, 0113 | D2: 011, 012, 013 | E2: Akkerbouw en fruitteelt (bedrijfsgebouwen) | F2: 10 | G2: 2 | H2: 2 | I2: 30 | J2: =FALSE() -> FALSE | K2: 30 | L2: 2 | M2: =FALSE() -> FALSE | N2: =COUNTIF($F$2:$F$560,"<"&F2)+(COUNTIF($F$2:$F$560,F2)+1)/2 -> 164 | O2: =COUNTIF($H$2:$H$560,"<"&H2)+(COUNTIF($H$2:$H$560,H2)+1)/2 -> 89 | P2: =IF(J2=FALSE(),COUNTIFS($J$2:$J$560,FALSE(),$F$2:$F$560,"<"&F2)+(COUNTIFS($J$2:$J$560,FALSE(),$F$2:$F$560,F2)+1)/2,"") -> 161.5 | Q2: =IF(J2=FALSE(),COUNTIFS($J$2:$J$560,FALSE(),$H$2:$H$560,"<"&H2)+(COUNTIFS($J$2:$J$560,FALSE(),$H$2:$H$560,H2)+1)/2,"") -> 71.5 | R2: =COUNTIF($L$2:$L$560,"<"&L2)+(COUNTIF($L$2:$L$560,L2)+1)/2 -> 101.5 | S2: =MATCH(F2,Codetabel!$G$2:$G$12,0)-1 -> 1 | T2: =H2-1 -> 1
A3: B1 | B3: 6 | C3: 0112 | D3: 011, 012, 013 | E3: - bedrijfsgebouwen | F3: 10 | G3: 2 | H3: 2 | I3: 30 | J3: =FALSE() -> FALSE | K3: 30 | L3: 2 | M3: =FALSE() -> FALSE | N3: =COUNTIF($F$2:$F$560,"<"&F3)+(COUNTIF($F$2:$F$560,F3)+1)/2 -> 164 | O3: =COUNTIF($H$2:$H$560,"<"&H3)+(COUNTIF($H$2:$H$560,H3)+1)/2 -> 89 | P3: =IF(J3=FALSE(),COUNTIFS($J$2:$J$560,FALSE(),$F$2:$F$560,"<"&F3)+(COUNTIFS($J$2:$J$560,FALSE(),$F$2:$F$560,F3)+1)/2,"") -> 161.5 | Q3: =IF(J3=FALSE(),COUNTIFS($J$2:$J$560,FALSE(),$H$2:$H$560,"<"&H3)+(COUNTIFS($J$2:$J$560,FALSE(),$H$2:$H$560,H3)+1)/2,"") -> 71.5 | R3: =COUNTIF($L$2:$L$560,"<"&L3)+(COUNTIF($L$2:$L$560,L3)+1)/2 -> 101.5 | S3: =MATCH(F3,Codetabel!$G$2:$G$12,0)-1 -> 1 | T3: =H3-1 -> 1
A4: B1 | B4: 7 | C4: 0112 | D4: 011, 012, 013 | E4: - kassen zonder verwarming | F4: 10 | G4: 2 | H4: 2 | I4: 30 | J4: =FALSE() -> FALSE | K4: 30 | L4: 2 | M4: =FALSE() -> FALSE | N4: =COUNTIF($F$2:$F$560,"<"&F4)+(COUNTIF($F$2:$F$560,F4)+1)/2 -> 164 | O4: =COUNTIF($H$2:$H$560,"<"&H4)+(COUNTIF($H$2:$H$560,H4)+1)/2 -> 89 | P4: =IF(J4=FALSE(),COUNTIFS($J$2:$J$560,FALSE(),$F$2:$F$560,"<"&F4)+(COUNTIFS($J$2:$J$560,FALSE(),$F$2:$F$560,F4)+1)/2,"") -> 161.5 | Q4: =IF(J4=FALSE(),COUNTIFS($J$2:$J$560,FALSE(),$H$2:$H$560,"<"&H4)+(COUNTIFS($J$2:$J$560,FALSE(),$H$2:$H$560,H4)+1)/2,"") -> 71.5 | R4: =COUNTIF($L$2:$L$560,"<"&L4)+(COUNTIF($L$2:$L$560,L4)+1)/2 -> 101.5 | S4: =MATCH(F4,Codetabel!$G$2:$G$12,0)-1 -> 1 | T4: =H4-1 -> 1
A5: B1 | B5: 8 | C5: 0112 | D5: 011, 012, 013 | E5: - kassen met gasverwarming | F5: 10 | G5: 2 | H5: 2 | I5: 30 | J5: =FALSE() -> FALSE | K5: 30 | L5: 2 | M5: =FALSE() -> FALSE | N5: =COUNTIF($F$2:$F$560,"<"&F5)+(COUNTIF($F$2:$F$560,F5)+1)/2 -> 164 | O5: =COUNTIF($H$2:$H$560,"<"&H5)+(COUNTIF($H$2:$H$560,H5)+1)/2 -> 89 | P5: =IF(J5=FALSE(),COUNTIFS($J$2:$J$560,FALSE(),$F$2:$F$560,"<"&F5)+(COUNTIFS($J$2:$J$560,FALSE(),$F$2:$F$560,F5)+1)/2,"") -> 161.5 | Q5: =IF(J5=FALSE(),COUNTIFS($J$2:$J$560,FALSE(),$H$2:$H$560,"<"&H5)+(COUNTIFS($J$2:$J$560,FALSE(),$H$2:$H$560,H5)+1)/2,"") -> 71.5 | R5: =COUNTIF($L$2:$L$560,"<"&L5)+(COUNTIF($L$2:$L$560,L5)+1)/2 -> 101.5 | S5: =MATCH(F5,Codetabel!$G$2:$G$12,0)-1 -> 1 | T5: =H5-1 -> 1
A6: B1 | B6: 9 | C6: 0112 | D6: 0113 | E6: - champignonkwekerijen (algemeen) | F6: 30 | G6: 2 | H6: 2 | I6: 30 | J6: =TRUE() -> TRUE | K6: 30 | L6: 2 | M6: =FALSE() -> FALSE | N6: =COUNTIF($F$2:$F$560,"<"&F6)+(COUNTIF($F$2:$F$560,F6)+1)/2 -> 257.5 | O6: =COUNTIF($H$2:$H$560,"<"&H6)+(COUNTIF($H$2:$H$560,H6)+1)/2 -> 89 | P6: =IF(J6=FALSE(),COUNTIFS($J$2:$J$560,FALSE(),$F$2:$F$560,"<"&F6)+(COUNTIFS($J$2:$J$560,FALSE(),$F$2:$F$560,F6)+1)/2,"") | Q6: =IF(J6=FALSE(),COUNTIFS($J$2:$J$560,FALSE(),$H$2:$H$560,"<"&H6)+(COUNTIFS($J$2:$J$560,FALSE(),$H$2:$H$560,H6)+1)/2,"") | R6: =COUNTIF($L$2:$L$560,"<"&L6)+(COUNTIF($L$2:$L$560,L6)+1)/2 -> 101.5 | S6: =MATCH(F6,Codetabel!$G$2:$G$12,0)-1 -> 2 | T6: =H6-1 -> 1
A7: B1 | B7: 10 | C7: 0112 | D7: 0113 | E7: - champignonkwekerijen met mestfermentatie | F7: 100 | G7: 3.2 | H7: 4 | I7: 100 | J7: =TRUE() -> TRUE | K7: 30 | L7: 2 | M7: =FALSE() -> FALSE | N7: =COUNTIF($F$2:$F$560,"<"&F7)+(COUNTIF($F$2:$F$560,F7)+1)/2 -> 415.5 | O7: =COUNTIF($H$2:$H$560,"<"&H7)+(COUNTIF($H$2:$H$560,H7)+1)/2 -> 266.5 | P7: =IF(J7=FALSE(),COUNTIFS($J$2:$J$560,FALSE(),$F$2:$F$560,"<"&F7)+(COUNTIFS($J$2:$J$560,FALSE(),$F$2:$F$560,F7)+1)/2,"") | Q7: =IF(J7=FALSE(),COUNTIFS($J$2:$J$560,FALSE(),$H$2:$H$560,"<"&H7)+(COUNTIFS($J$2:$J$560,FALSE(),$H$2:$H$560,H7)+1)/2,"") | R7: =COUNTIF($L$2:$L$560,"<"&L7)+(COUNTIF($L$2:$L$560,L7)+1)/2 -> 101.5 | S7: =MATCH(F7,Codetabel!$G$2:$G$12,0)-1 -> 4 | T7: =H7-1 -> 3
A8: B1 | B8: 11 | C8: 0112 | D8: 0163 | E8: - bloembollendroog- en prepareerbedrijven | F8: 30 | G8: 2 | H8: 2 | I8: 30 | J8: =TRUE() -> TRUE | K8: 30 | L8: 2 | M8: =FALSE() -> FALSE | N8: =COUNTIF($F$2:$F$560,"<"&F8)+(COUNTIF($F$2:$F$560,F8)+1)/2 -> 257.5 | O8: =COUNTIF($H$2:$H$560,"<"&H8)+(COUNTIF($H$2:$H$560,H8)+1)/2 -> 89 | P8: =IF(J8=FALSE(),COUNTIFS($J$2:$J$560,FALSE(),$F$2:$F$560,"<"&F8)+(COUNTIFS($J$2:$J$560,FALSE(),$F$2:$F$560,F8)+1)/2,"") | Q8: =IF(J8=FALSE(),COUNTIFS($J$2:$J$560,FALSE(),$H$2:$H$560,"<"&H8)+(COUNTIFS($J$2:$J$560,FALSE(),$H$2:$H$560,H8)+1)/2,"") | R8: =COUNTIF($L$2:$L$560,"<"&L8)+(COUNTIF($L$2:$L$560,L8)+1)/2 -> 101.5 | S8: =MATCH(F8,Codetabel!$G$2:$G$12,0)-1 -> 2 | T8: =H8-1 -> 1
A9: B1 | B9: 12 | C9: 0112 | D9: 011 | E9: - witlofkwekerijen (algemeen) | F9: 30 | G9: 2 | H9: 2 | I9: 30 | J9: =TRUE() -> TRUE | K9: 30 | L9: 2 | M9: =FALSE() -> FALSE | N9: =COUNTIF($F$2:$F$560,"<"&F9)+(COUNTIF($F$2:$F$560,F9)+1)/2 -> 257.5 | O9: =COUNTIF($H$2:$H$560,"<"&H9)+(COUNTIF($H$2:$H$560,H9)+1)/2 -> 89 | P9: =IF(J9=FALSE(),COUNTIFS($J$2:$J$560,FALSE(),$F$2:$F$560,"<"&F9)+(COUNTIFS($J$2:$J$560,FALSE(),$F$2:$F$560,F9)+1)/2,"") | Q9: =IF(J9=FALSE(),COUNTIFS($J$2:$J$560,FALSE(),$H$2:$H$560,"<"&H9)+(COUNTIFS($J$2:$J$560,FALSE(),$H$2:$H$560,H9)+1)/2,"") | R9: =COUNTIF($L$2:$L$560,"<"&L9)+(COUNTIF($L$2:$L$560,L9)+1)/2 -> 101.5 | S9: =MATCH(F9,Codetabel!$G$2:$G$12,0)-1 -> 2 | T9: =H9-1 -> 1
A10: B1 | B10: 13 | C10: 0121 | D10: 0141, 0142 | E10: Fokken en houden van rundvee | F10: 100 | G10: 3.2 | H10: 4 | I10: 100 | J10: =TRUE() -> TRUE | K10: 30 | L10: 2 | M10: =FALSE() -> FALSE | N10: =COUNTIF($F$2:$F$560,"<"&F10)+(COUNTIF($F$2:$F$560,F10)+1)/2 -> 415.5 | O10: =COUNTIF($H$2:$H$560,"<"&H10)+(COUNTIF($H$2:$H$560,H10)+1)/2 -> 266.5 | P10: =IF(J10=FALSE(),COUNTIFS($J$2:$J$560,FALSE(),$F$2:$F$560,"<"&F10)+(COUNTIFS($J$2:$J$560,FALSE(),$F$2:$F$560,F10)+1)/2,"") | Q10: =IF(J10=FALSE(),COUNTIFS($J$2:$J$560,FALSE(),$H$2:$H$560,"<"&H10)+(COUNTIFS($J$2:$J$560,FALSE(),$H$2:$H$560,H10)+1)/2,"") | R10: =COUNTIF($L$2:$L$560,"<"&L10)+(COUNTIF($L$2:$L$560,L10)+1)/2 -> 101.5 | S10: =MATCH(F10,Codetabel!$G$2:$G$12,0)-1 -> 4 | T10: =H10-1 -> 3
A11: B1 | B11: 15 | C11: 0122 | D11: 0143 | E11: - paardenfokkerijen | F11: 50 | G11: 3.1 | H11: 3 | I11: 50 | J11: =TRUE() -> TRUE | K11: 30 | L11: 2 | M11: =FALSE() -> FALSE | N11: =COUNTIF($F$2:$F$560,"<"&F11)+(COUNTIF($F$2:$F$560,F11)+1)/2 -> 343.5 | O11: =COUNTIF($H$2:$H$560,"<"&H11)+(COUNTIF($H$2:$H$560,H11)+1)/2 -> 175.5 | P11: =IF(J11=FALSE(),COUNTIFS($J$2:$J$560,FALSE(),$F$2:$F$560,"<"&F11)+(COUNTIFS($J$2:$J$560,FALSE(),$F$2:$F$560,F11)+1)/2,"") | Q11: =IF(J11=FALSE(),COUNTIFS($J$2:$J$560,FALSE(),$H$2:$H$560,"<"&H11)+(COUNTIFS($J$2:$J$560,FALSE(),$H$2:$H$560,H11)+1)/2,"") | R11: =COUNTIF($L$2:$L$560,"<"&L11)+(COUNTIF($L$2:$L$560,L11)+1)/2 -> 101.5 | S11: =MATCH(F11,Codetabel!$G$2:$G$12,0)-1 -> 3 | T11: =H11-1 -> 2
A12: B1 | B12: 16 | C12: 0122 | D12: 0145 | E12: - overige graasdieren | F12: 50 | G12: 3.1 | H12: 3 | I12: 50 | J12: =TRUE() -> TRUE | K12: 30 | L12: 2 | M12: =FALSE() -> FALSE | N12: =COUNTIF($F$2:$F$560,"<"&F12)+(COUNTIF($F$2:$F$560,F12)+1)/2 -> 343.5 | O12: =COUNTIF($H$2:$H$560,"<"&H12)+(COUNTIF($H$2:$H$560,H12)+1)/2 -> 175.5 | P12: =IF(J12=FALSE(),COUNTIFS($J$2:$J$560,FALSE(),$F$2:$F$560,"<"&F12)+(COUNTIFS($J$2:$J$560,FALSE(),$F$2:$F$560,F12)+1)/2,"") | Q12: =IF(J12=FALSE(),COUNTIFS($J$2:$J$560,FALSE(),$H$2:$H$560,"<"&H12)+(COUNTIFS($J$2:$J$560,FALSE(),$H$2:$H$560,H12)+1)/2,"") | R12: =COUNTIF($L$2:$L$560,"<"&L12)+(COUNTIF($L$2:$L$560,L12)+1)/2 -> 101.5 | S12: =MATCH(F12,Codetabel!$G$2:$G$12,0)-1 -> 3 | T12: =H12-1 -> 2
A13: B1 | B13: 17 | C13: 0123 | D13: 0146 | E13: Fokken en houden van varkens | F13: 200 | G13: 4.1 | H13: 5 | I13: 200 | J13: =TRUE() -> TRUE | K13: 50 | L13: 3 | M13: =FALSE() -> FALSE | N13: =COUNTIF($F$2:$F$560,"<"&F13)+(COUNTIF($F$2:$F$560,F13)+1)/2 -> 471.5 | O13: =COUNTIF($H$2:$H$560,"<"&H13)+(COUNTIF($H$2:$H$560,H13)+1)/2 -> 348.5 | P13: =IF(J13=FALSE(),COUNTIFS($J$2:$J$560,FALSE(),$F$2:$F$560,"<"&F13)+(COUNTIFS($J$2:$J$560,FALSE(),$F$2:$F$560,F13)+1)/2,"") | Q13: =IF(J13=FALSE(),COUNTIFS($J$2:$J$560,FALSE(),$H$2:$H$560,"<"&H13)+(COUNTIFS($J$2:$J$560,FALSE(),$H$2:$H$560,H13)+1)/2,"") | R13: =COUNTIF($L$2:$L$560,"<"&L13)+(COUNTIF($L$2:$L$560,L13)+1)/2 -> 204 | S13: =MATCH(F13,Codetabel!$G$2:$G$12,0)-1 -> 5 | T13: =H13-1 -> 4
A14: B1 | B14: 19 | C14: 0124 | D14: 0147 | E14: - legkippen | F14: 200 | G14: 4.1 | H14: 5 | I14: 200 | J14: =TRUE() -> TRUE | K14: 50 | L14: 3 | M14: =FALSE() -> FALSE | N14: =COUNTIF($F$2:$F$560,"<"&F14)+(COUNTIF($F$2:$F$560,F14)+1)/2 -> 471.5 | O14: =COUNTIF($H$2:$H$560,"<"&H14)+(COUNTIF($H$2:$H$560,H14)+1)/2 -> 348.5 | P14: =IF(J14=FALSE(),COUNTIFS($J$2:$J$560,FALSE(),$F$2:$F$560,"<"&F14)+(COUNTIFS($J$2:$J$560,FALSE(),$F$2:$F$560,F14)+1)/2,"") | Q14: =IF(J14=FALSE(),COUNTIFS($J$2:$J$560,FALSE(),$H$2:$H$560,"<"&H14)+(COUNTIFS($J$2:$J$560,FALSE(),$H$2:$H$560,H14)+1)/2,"") | R14: =COUNTIF($L$2:$L$560,"<"&L14)+(COUNTIF($L$2:$L$560,L14)+1)/2 -> 204 | S14: =MATCH(F14,Codetabel!$G$2:$G$12,0)-1 -> 5 | T14: =H14-1 -> 4
A15: B1 | B15: 20 | C15: 0124 | D15: 0147 | E15: - opfokkippen en mestkuikens | F15: 200 | G15: 4.1 | H15: 5 | I15: 200 | J15: =TRUE() -> TRUE | K15: 50 | L15: 3 | M15: =FALSE() -> FALSE | N15: =COUNTIF($F$2:$F$560,"<"&F15)+(COUNTIF($F$2:$F$560,F15)+1)/2 -> 471.5 | O15: =COUNTIF($H$2:$H$560,"<"&H15)+(COUNTIF($H$2:$H$560,H15)+1)/2 -> 348.5 | P15: =IF(J15=FALSE(),COUNTIFS($J$2:$J$560,FALSE(),$F$2:$F$560,"<"&F15)+(COUNTIFS($J$2:$J$560,FALSE(),$F$2:$F$560,F15)+1)/2,"") | Q15: =IF(J15=FALSE(),COUNTIFS($J$2:$J$560,FALSE(),$H$2:$H$560,"<"&H15)+(COUNTIFS($J$2:$J$560,FALSE(),$H$2:$H$560,H15)+1)/2,"") | R15: =COUNTIF($L$2:$L$560,"<"&L15)+(COUNTIF($L$2:$L$560,L15)+1)/2 -> 204 | S15: =MATCH(F15,Codetabel!$G$2:$G$12,0)-1 -> 5 | T15: =H15-1 -> 4
A16: B1 | B16: 21 | C16: 0124 | D16: 0147 | E16: - eenden en ganzen | F16: 200 | G16: 4.1 | H16: 5 | I16: 200 | J16: =TRUE() -> TRUE | K16: 50 | L16: 3 | M16: =FALSE() -> FALSE | N16: =COUNTIF($F$2:$F$560,"<"&F16)+(COUNTIF($F$2:$F$560,F16)+1)/2 -> 471.5 | O16: =COUNTIF($H$2:$H$560,"<"&H16)+(COUNTIF($H$2:$H$560,H16)+1)/2 -> 348.5 | P16: =IF(J16=FALSE(),COUNTIFS($J$2:$J$560,FALSE(),$F$2:$F$560,"<"&F16)+(COUNTIFS($J$2:$J$560,FALSE(),$F$2:$F$560,F16)+1)/2,"") | Q16: =IF(J16=FALSE(),COUNTIFS($J$2:$J$560,FALSE(),$H$2:$H$560,"<"&H16)+(COUNTIFS($J$2:$J$560,FALSE(),$H$2:$H$560,H16)+1)/2,"") | R16: =COUNTIF($L$2:$L$560,"<"&L16)+(COUNTIF($L$2:$L$560,L16)+1)/2 -> 204 | S16: =MATCH(F16,Codetabel!$G$2:$G$12,0)-1 -> 5 | T16: =H16-1 -> 4
A17: B1 | B17: 22 | C17: 0124 | D17: 0147 | E17: - overig pluimvee | F17: 100 | G17: 3.2 | H17: 4 | I17: 100 | J17: =TRUE() -> TRUE | K17: 50 | L17: 3 | M17: =FALSE() -> FALSE | N17: =COUNTIF($F$2:$F$560,"<"&F17)+(COUNTIF($F$2:$F$560,F17)+1)/2 -> 415.5 | O17: =COUNTIF($H$2:$H$560,"<"&H17)+(COUNTIF($H$2:$H$560,H17)+1)/2 -> 266.5 | P17: =IF(J17=FALSE(),COUNTIFS($J$2:$J$560,FALSE(),$F$2:$F$560,"<"&F17)+(COUNTIFS($J$2:$J$560,FALSE(),$F$2:$F$560,F17)+1)/2,"") | Q17: =IF(J17=FALSE(),COUNTIFS($J$2:$J$560,FALSE(),$H$2:$H$560,"<"&H17)+(COUNTIFS($J$2:$J$560,FALSE(),$H$2:$H$560,H17)+1)/2,"") | R17: =COUNTIF($L$2:$L$560,"<"&L17)+(COUNTIF($L$2:$L$560,L17)+1)/2 -> 204 | S17: =MATCH(F17,Codetabel!$G$2:$G$12,0)-1 -> 4 | T17: =H17-1 -> 3
... A19: B1 | B19: 25 | C19: 0125 | D19: 0149 | E19: - konijnen | F19: 100 | G19: 3.2 | H19: 4 | I19: 100 | J19: =TRUE() -> TRUE | K19: 30 | L19: 2 | M19: =FALSE() -> FALSE | N19: =COUNTIF($F$2:$F$560,"<"&F19)+(COUNTIF($F$2:$F$560,F19)+1)/2 -> 415.5 | O19: =COUNTIF($H$2:$H$560,"<"&H19)+(COUNTIF($H$2:$H$560,H19)+1)/2 -> 266.5 | P19: =IF(J19=FALSE(),COUNTIFS($J$2:$J$560,FALSE(),$F$2:$F$560,"<"&F19)+(COUNTIFS($J$2:$J$560,FALSE(),$F$2:$F$560,F19)+1)/2,"") | Q19: =IF(J19=FALSE(),COUNTIFS($J$2:$J$560,FALSE(),$H$2:$H$560,"<"&H19)+(COUNTIFS($J$2:$J$560,FALSE(),$H$2:$H$560,H19)+1)/2,"") | R19: =COUNTIF($L$2:$L$560,"<"&L19)+(COUNTIF($L$2:$L$560,L19)+1)/2 -> 101.5 | S19: =MATCH(F19,Codetabel!$G$2:$G$12,0)-1 -> 4 | T19: =H19-1 -> 3
A20: B1 | B20: 26 | C20: 0125 | D20: 0149 | E20: - huisdieren | F20: 30 | G20: 3.1 | H20: 3 | I20: 50 | J20: =FALSE() -> FALSE | K20: 50 | L20: 3 | M20: =FALSE() -> FALSE | N20: =COUNTIF($F$2:$F$560,"<"&F20)+(COUNTIF($F$2:$F$560,F20)+1)/2 -> 257.5 | O20: =COUNTIF($H$2:$H$560,"<"&H20)+(COUNTIF($H$2:$H$560,H20)+1)/2 -> 175.5 | P20: =IF(J20=FALSE(),COUNTIFS($J$2:$J$560,FALSE(),$F$2:$F$560,"<"&F20)+(COUNTIFS($J$2:$J$560,FALSE(),$F$2:$F$560,F20)+1)/2,"") -> 240 | Q20: =IF(J20=FALSE(),COUNTIFS($J$2:$J$560,FALSE(),$H$2:$H$560,"<"&H20)+(COUNTIFS($J$2:$J$560,FALSE(),$H$2:$H$560,H20)+1)/2,"") -> 132.5 | R20: =COUNTIF($L$2:$L$560,"<"&L20)+(COUNTIF($L$2:$L$560,L20)+1)/2 -> 204 | S20: =MATCH(F20,Codetabel!$G$2:$G$12,0)-1 -> 2 | T20: =H20-1 -> 2
A21: B1 | B21: 27 | C21: 0125 | D21: 0149 | E21: - maden, wormen e.d. | F21: 100 | G21: 3.2 | H21: 4 | I21: 100 | J21: =TRUE() -> TRUE | K21: 30 | L21: 2 | M21: =FALSE() -> FALSE | N21: =COUNTIF($F$2:$F$560,"<"&F21)+(COUNTIF($F$2:$F$560,F21)+1)/2 -> 415.5 | O21: =COUNTIF($H$2:$H$560,"<"&H21)+(COUNTIF($H$2:$H$560,H21)+1)/2 -> 266.5 | P21: =IF(J21=FALSE(),COUNTIFS($J$2:$J$560,FALSE(),$F$2:$F$560,"<"&F21)+(COUNTIFS($J$2:$J$560,FALSE(),$F$2:$F$560,F21)+1)/2,"") | Q21: =IF(J21=FALSE(),COUNTIFS($J$2:$J$560,FALSE(),$H$2:$H$560,"<"&H21)+(COUNTIFS($J$2:$J$560,FALSE(),$H$2:$H$560,H21)+1)/2,"") | R21: =COUNTIF($L$2:$L$560,"<"&L21)+(COUNTIF($L$2:$L$560,L21)+1)/2 -> 101.5 | S21: =MATCH(F21,Codetabel!$G$2:$G$12,0)-1 -> 4 | T21: =H21-1 -> 3
A22: B1 | B22: 28 | C22: 0125 | D22: 0149 | E22: - bijen | F22: 10 | G22: 2 | H22: 2 | I22: 30 | J22: =FALSE() -> FALSE | K22: 30 | L22: 2 | M22: =FALSE() -> FALSE | N22: =COUNTIF($F$2:$F$560,"<"&F22)+(COUNTIF($F$2:$F$560,F22)+1)/2 -> 164 | O22: =COUNTIF($H$2:$H$560,"<"&H22)+(COUNTIF($H$2:$H$560,H22)+1)/2 -> 89 | P22: =IF(J22=FALSE(),COUNTIFS($J$2:$J$560,FALSE(),$F$2:$F$560,"<"&F22)+(COUNTIFS($J$2:$J$560,FALSE(),$F$2:$F$560,F22)+1)/2,"") -> 161.5 | Q22: =IF(J22=FALSE(),COUNTIFS($J$2:$J$560,FALSE(),$H$2:$H$560,"<"&H22)+(COUNTIFS($J$2:$J$560,FALSE(),$H$2:$H$560,H22)+1)/2,"") -> 71.5 | R22: =COUNTIF($L$2:$L$560,"<"&L22)+(COUNTIF($L$2:$L$560,L22)+1)/2 -> 101.5 | S22: =MATCH(F22,Codetabel!$G$2:$G$12,0)-1 -> 1 | T22: =H22-1 -> 1
A23: B1 | B23: 29 | C23: 0125 | D23: 0149 | E23: - overige dieren | F23: 30 | G23: 2 | H23: 2 | I23: 30 | J23: =TRUE() -> TRUE | K23: 30 | L23: 2 | M23: =FALSE() -> FALSE | N23: =COUNTIF($F$2:$F$560,"<"&F23)+(COUNTIF($F$2:$F$560,F23)+1)/2 -> 257.5 | O23: =COUNTIF($H$2:$H$560,"<"&H23)+(COUNTIF($H$2:$H$560,H23)+1)/2 -> 89 | P23: =IF(J23=FALSE(),COUNTIFS($J$2:$J$560,FALSE(),$F$2:$F$560,"<"&F23)+(COUNTIFS($J$2:$J$560,FALSE(),$F$2:$F$560,F23)+1)/2,"") | Q23: =IF(J23=FALSE(),COUNTIFS($J$2:$J$560,FALSE(),$H$2:$H$560,"<"&H23)+(COUNTIFS($J$2:$J$560,FALSE(),$H$2:$H$560,H23)+1)/2,"") | R23: =COUNTIF($L$2:$L$560,"<"&L23)+(COUNTIF($L$2:$L$560,L23)+1)/2 -> 101.5 | S23: =MATCH(F23,Codetabel!$G$2:$G$12,0)-1 -> 2 | T23: =H23-1 -> 1
A24: B1 | B24: 30 | C24: 0130 | D24: 0150 | E24: Akker-en/of tuinbouw in combinatie met het fokken en houden van dieren (niet intensief) | F24: 100 | G24: 3.2 | H24: 4 | I24: 100 | J24: =TRUE() -> TRUE | K24: 30 | L24: 2 | M24: =FALSE() -> FALSE | N24: =COUNTIF($F$2:$F$560,"<"&F24)+(COUNTIF($F$2:$F$560,F24)+1)/2 -> 415.5 | O24: =COUNTIF($H$2:$H$560,"<"&H24)+(COUNTIF($H$2:$H$560,H24)+1)/2 -> 266.5 | P24: =IF(J24=FALSE(),COUNTIFS($J$2:$J$560,FALSE(),$F$2:$F$560,"<"&F24)+(COUNTIFS($J$2:$J$560,FALSE(),$F$2:$F$560,F24)+1)/2,"") | Q24: =IF(J24=FALSE(),COUNTIFS($J$2:$J$560,FALSE(),$H$2:$H$560,"<"&H24)+(COUNTIFS($J$2:$J$560,FALSE(),$H$2:$H$560,H24)+1)/2,"") | R24: =COUNTIF($L$2:$L$560,"<"&L24)+(COUNTIF($L$2:$L$560,L24)+1)/2 -> 101.5 | S24: =MATCH(F24,Codetabel!$G$2:$G$12,0)-1 -> 4 | T24: =H24-1 -> 3
A25: B1 | B25: 32 | C25: 014 | D25: 016 | E25: - algemeen (o.a. loonbedrijven): b.o. > 500 m² | F25: 30 | G25: 3.1 | H25: 3 | I25: 50 | J25: =FALSE() -> FALSE | K25: 50 | L25: 3 | M25: =FALSE() -> FALSE | N25: =COUNTIF($F$2:$F$560,"<"&F25)+(COUNTIF($F$2:$F$560,F25)+1)/2 -> 257.5 | O25: =COUNTIF($H$2:$H$560,"<"&H25)+(COUNTIF($H$2:$H$560,H25)+1)/2 -> 175.5 | P25: =IF(J25=FALSE(),COUNTIFS($J$2:$J$560,FALSE(),$F$2:$F$560,"<"&F25)+(COUNTIFS($J$2:$J$560,FALSE(),$F$2:$F$560,F25)+1)/2,"") -> 240 | Q25: =IF(J25=FALSE(),COUNTIFS($J$2:$J$560,FALSE(),$H$2:$H$560,"<"&H25)+(COUNTIFS($J$2:$J$560,FALSE(),$H$2:$H$560,H25)+1)/2,"") -> 132.5 | R25: =COUNTIF($L$2:$L$560,"<"&L25)+(COUNTIF($L$2:$L$560,L25)+1)/2 -> 204 | S25: =MATCH(F25,Codetabel!$G$2:$G$12,0)-1 -> 2 | T25: =H25-1 -> 2
A26: B1 | B26: 33 | C26: 014 | D26: 016 | E26: - algemeen (o.a. loonbedrijven): b.o.<= 500 m² | F26: 30 | G26: 2 | H26: 2 | I26: 30 | J26: =TRUE() -> TRUE | K26: 30 | L26: 2 | M26: =FALSE() -> FALSE | N26: =COUNTIF($F$2:$F$560,"<"&F26)+(COUNTIF($F$2:$F$560,F26)+1)/2 -> 257.5 | O26: =COUNTIF($H$2:$H$560,"<"&H26)+(COUNTIF($H$2:$H$560,H26)+1)/2 -> 89 | P26: =IF(J26=FALSE(),COUNTIFS($J$2:$J$560,FALSE(),$F$2:$F$560,"<"&F26)+(COUNTIFS($J$2:$J$560,FALSE(),$F$2:$F$560,F26)+1)/2,"") | Q26: =IF(J26=FALSE(),COUNTIFS($J$2:$J$560,FALSE(),$H$2:$H$560,"<"&H26)+(COUNTIFS($J$2:$J$560,FALSE(),$H$2:$H$560,H26)+1)/2,"") | R26: =COUNTIF($L$2:$L$560,"<"&L26)+(COUNTIF($L$2:$L$560,L26)+1)/2 -> 101.5 | S26: =MATCH(F26,Codetabel!$G$2:$G$12,0)-1 -> 2 | T26: =H26-1 -> 1
A27: B1 | B27: 34 | C27: 014 | D27: 016 | E27: - plantsoenendiensten en hoveniersbedrijven: b.o. > 500 m² | F27: 30 | G27: 3.1 | H27: 3 | I27: 50 | J27: =FALSE() -> FALSE | K27: 50 | L27: 3 | M27: =FALSE() -> FALSE | N27: =COUNTIF($F$2:$F$560,"<"&F27)+(COUNTIF($F$2:$F$560,F27)+1)/2 -> 257.5 | O27: =COUNTIF($H$2:$H$560,"<"&H27)+(COUNTIF($H$2:$H$560,H27)+1)/2 -> 175.5 | P27: =IF(J27=FALSE(),COUNTIFS($J$2:$J$560,FALSE(),$F$2:$F$560,"<"&F27)+(COUNTIFS($J$2:$J$560,FALSE(),$F$2:$F$560,F27)+1)/2,"") -> 240 | Q27: =IF(J27=FALSE(),COUNTIFS($J$2:$J$560,FALSE(),$H$2:$H$560,"<"&H27)+(COUNTIFS($J$2:$J$560,FALSE(),$H$2:$H$560,H27)+1)/2,"") -> 132.5 | R27: =COUNTIF($L$2:$L$560,"<"&L27)+(COUNTIF($L$2:$L$560,L27)+1)/2 -> 204 | S27: =MATCH(F27,Codetabel!$G$2:$G$12,0)-1 -> 2 | T27: =H27-1 -> 2
A28: B1 | B28: 35 | C28: 014 | D28: 016 | E28: - plantsoenendiensten en hoveniersbedrijven: b.o. <= 500 m² | F28: 30 | G28: 2 | H28: 2 | I28: 30 | J28: =TRUE() -> TRUE | K28: 30 | L28: 2 | M28: =FALSE() -> FALSE | N28: =COUNTIF($F$2:$F$560,"<"&F28)+(COUNTIF($F$2:$F$560,F28)+1)/2 -> 257.5 | O28: =COUNTIF($H$2:$H$560,"<"&H28)+(COUNTIF($H$2:$H$560,H28)+1)/2 -> 89 | P28: =IF(J28=FALSE(),COUNTIFS($J$2:$J$560,FALSE(),$F$2:$F$560,"<"&F28)+(COUNTIFS($J$2:$J$560,FALSE(),$F$2:$F$560,F28)+1)/2,"") | Q28: =IF(J28=FALSE(),COUNTIFS($J$2:$J$560,FALSE(),$H$2:$H$560,"<"&H28)+(COUNTIFS($J$2:$J$560,FALSE(),$H$2:$H$560,H28)+1)/2,"") | R28: =COUNTIF($L$2:$L$560,"<"&L28)+(COUNTIF($L$2:$L$560,L28)+1)/2 -> 101.5 | S28: =MATCH(F28,Codetabel!$G$2:$G$12,0)-1 -> 2 | T28: =H28-1 -> 1
A29: B1 | B29: 36 | C29: 0142 | D29: 0162 | E29: KI-stations | F29: 30 | G29: 2 | H29: 2 | I29: 30 | J29: =TRUE() -> TRUE | K29: 30 | L29: 2 | M29: =FALSE() -> FALSE | N29: =COUNTIF($F$2:$F$560,"<"&F29)+(COUNTIF($F$2:$F$560,F29)+1)/2 -> 257.5 | O29: =COUNTIF($H$2:$H$560,"<"&H29)+(COUNTIF($H$2:$H$560,H29)+1)/2 -> 89 | P29: =IF(J29=FALSE(),COUNTIFS($J$2:$J$560,FALSE(),$F$2:$F$560,"<"&F29)+(COUNTIFS($J$2:$J$560,FALSE(),$F$2:$F$560,F29)+1)/2,"") | Q29: =IF(J29=FALSE(),COUNTIFS($J$2:$J$560,FALSE(),$H$2:$H$560,"<"&H29)+(COUNTIFS($J$2:$J$560,FALSE(),$H$2:$H$560,H29)+1)/2,"") | R29: =COUNTIF($L$2:$L$560,"<"&L29)+(COUNTIF($L$2:$L$560,L29)+1)/2 -> 101.5 | S29: =MATCH(F29,Codetabel!$G$2:$G$12,0)-1 -> 2 | T29: =H29-1 -> 1
A30: B1 | B30: 39 | C30: 020 | D30: 021, 022, 024 | E30: Bosbouwbedrijven | F30: 10 | G30: 3.1 | H30: 3 | I30: 50 | J30: =FALSE() -> FALSE | K30: 50 | L30: 3 | M30: =FALSE() -> FALSE | N30: =COUNTIF($F$2:$F$560,"<"&F30)+(COUNTIF($F$2:$F$560,F30)+1)/2 -> 164 | O30: =COUNTIF($H$2:$H$560,"<"&H30)+(COUNTIF($H$2:$H$560,H30)+1)/2 -> 175.5 | P30: =IF(J30=FALSE(),COUNTIFS($J$2:$J$560,FALSE(),$F$2:$F$560,"<"&F30)+(COUNTIFS($J$2:$J$560,FALSE(),$F$2:$F$560,F30)+1)/2,"") -> 161.5 | Q30: =IF(J30=FALSE(),COUNTIFS($J$2:$J$560,FALSE(),$H$2:$H$560,"<"&H30)+(COUNTIFS($J$2:$J$560,FALSE(),$H$2:$H$560,H30)+1)/2,"") -> 132.5 | R30: =COUNTIF($L$2:$L$560,"<"&L30)+(COUNTIF($L$2:$L$560,L30)+1)/2 -> 204 | S30: =MATCH(F30,Codetabel!$G$2:$G$12,0)-1 -> 1 | T30: =H30-1 -> 2
A31: B1 | B31: 42 | C31: 0501.1 | D31: 0311 | E31: Zeevisserijbedrijven | F31: 100 | G31: 3.2 | H31: 4 | I31: 100 | J31: =TRUE() -> TRUE | K31: 100 | L31: 4 | M31: =FALSE() -> FALSE | N31: =COUNTIF($F$2:$F$560,"<"&F31)+(COUNTIF($F$2:$F$560,F31)+1)/2 -> 415.5 | O31: =COUNTIF($H$2:$H$560,"<"&H31)+(COUNTIF($H$2:$H$560,H31)+1)/2 -> 266.5 | P31: =IF(J31=FALSE(),COUNTIFS($J$2:$J$560,FALSE(),$F$2:$F$560,"<"&F31)+(COUNTIFS($J$2:$J$560,FALSE(),$F$2:$F$560,F31)+1)/2,"") | Q31: =IF(J31=FALSE(),COUNTIFS($J$2:$J$560,FALSE(),$H$2:$H$560,"<"&H31)+(COUNTIFS($J$2:$J$560,FALSE(),$H$2:$H$560,H31)+1)/2,"") | R31: =COUNTIF($L$2:$L$560,"<"&L31)+(COUNTIF($L$2:$L$560,L31)+1)/2 -> 305 | S31: =MATCH(F31,Codetabel!$G$2:$G$12,0)-1 -> 4 | T31: =H31-1 -> 3
A32: B1 | B32: 43 | C32: 0501.2 | D32: 0312 | E32: Binnenvisserijbedrijven | F32: 50 | G32: 3.1 | H32: 3 | I32: 50 | J32: =TRUE() -> TRUE | K32: 50 | L32: 3 | M32: =FALSE() -> FALSE | N32: =COUNTIF($F$2:$F$560,"<"&F32)+(COUNTIF($F$2:$F$560,F32)+1)/2 -> 343.5 | O32: =COUNTIF($H$2:$H$560,"<"&H32)+(COUNTIF($H$2:$H$560,H32)+1)/2 -> 175.5 | P32: =IF(J32=FALSE(),COUNTIFS($J$2:$J$560,FALSE(),$F$2:$F$560,"<"&F32)+(COUNTIFS($J$2:$J$560,FALSE(),$F$2:$F$560,F32)+1)/2,"") | Q32: =IF(J32=FALSE(),COUNTIFS($J$2:$J$560,FALSE(),$H$2:$H$560,"<"&H32)+(COUNTIFS($J$2:$J$560,FALSE(),$H$2:$H$560,H32)+1)/2,"") | R32: =COUNTIF($L$2:$L$560,"<"&L32)+(COUNTIF($L$2:$L$560,L32)+1)/2 -> 204 | S32: =MATCH(F32,Codetabel!$G$2:$G$12,0)-1 -> 3 | T32: =H32-1 -> 2
A33: B1 | B33: 45 | C33: 0502 | D33: 032 | E33: - oester-, mossel- en schelpenteeltbedrijven | F33: 100 | G33: 3.2 | H33: 4 | I33: 100 | J33: =TRUE() -> TRUE | K33: 50 | L33: 3 | M33: =FALSE() -> FALSE | N33: =COUNTIF($F$2:$F$560,"<"&F33)+(COUNTIF($F$2:$F$560,F33)+1)/2 -> 415.5 | O33: =COUNTIF($H$2:$H$560,"<"&H33)+(COUNTIF($H$2:$H$560,H33)+1)/2 -> 266.5 | P33: =IF(J33=FALSE(),COUNTIFS($J$2:$J$560,FALSE(),$F$2:$F$560,"<"&F33)+(COUNTIFS($J$2:$J$560,FALSE(),$F$2:$F$560,F33)+1)/2,"") | Q33: =IF(J33=FALSE(),COUNTIFS($J$2:$J$560,FALSE(),$H$2:$H$560,"<"&H33)+(COUNTIFS($J$2:$J$560,FALSE(),$H$2:$H$560,H33)+1)/2,"") | R33: =COUNTIF($L$2:$L$560,"<"&L33)+(COUNTIF($L$2:$L$560,L33)+1)/2 -> 204 | S33: =MATCH(F33,Codetabel!$G$2:$G$12,0)-1 -> 4 | T33: =H33-1 -> 3
A34: B1 | B34: 46 | C34: 0502 | D34: 032 | E34: - visteeltbedrijven | F34: 50 | G34: 3.1 | H34: 3 | I34: 50 | J34: =TRUE() -> TRUE | K34: 50 | L34: 3 | M34: =FALSE() -> FALSE | N34: =COUNTIF($F$2:$F$560,"<"&F34)+(COUNTIF($F$2:$F$560,F34)+1)/2 -> 343.5 | O34: =COUNTIF($H$2:$H$560,"<"&H34)+(COUNTIF($H$2:$H$560,H34)+1)/2 -> 175.5 | P34: =IF(J34=FALSE(),COUNTIFS($J$2:$J$560,FALSE(),$F$2:$F$560,"<"&F34)+(COUNTIFS($J$2:$J$560,FALSE(),$F$2:$F$560,F34)+1)/2,"") | Q34: =IF(J34=FALSE(),COUNTIFS($J$2:$J$560,FALSE(),$H$2:$H$560,"<"&H34)+(COUNTIFS($J$2:$J$560,FALSE(),$H$2:$H$560,H34)+1)/2,"") | R34: =COUNTIF($L$2:$L$560,"<"&L34)+(COUNTIF($L$2:$L$560,L34)+1)/2 -> 204 | S34: =MATCH(F34,Codetabel!$G$2:$G$12,0)-1 -> 3 | T34: =H34-1 -> 2
A35: B1 | B35: 49 | C35: 103 | D35: 089 | E35: Turfwinningbedrijven | F35: 50 | G35: 3.2 | H35: 4 | I35: 100 | J35: =FALSE() -> FALSE | K35: 100 | L35: 4 | M35: =FALSE() -> FALSE | N35: =COUNTIF($F$2:$F$560,"<"&F35)+(COUNTIF($F$2:$F$560,F35)+1)/2 -> 343.5 | O35: =COUNTIF($H$2:$H$560,"<"&H35)+(COUNTIF($H$2:$H$560,H35)+1)/2 -> 266.5 | P35: =IF(J35=FALSE(),COUNTIFS($J$2:$J$560,FALSE(),$F$2:$F$560,"<"&F35)+(COUNTIFS($J$2:$J$560,FALSE(),$F$2:$F$560,F35)+1)/2,"") -> 300.5 | Q35: =IF(J35=FALSE(),COUNTIFS($J$2:$J$560,FALSE(),$H$2:$H$560,"<"&H35)+(COUNTIFS($J$2:$J$560,FALSE(),$H$2:$H$560,H35)+1)/2,"") -> 193.5 | R35: =COUNTIF($L$2:$L$560,"<"&L35)+(COUNTIF($L$2:$L$560,L35)+1)/2 -> 305 | S35: =MATCH(F35,Codetabel!$G$2:$G$12,0)-1 -> 3 | T35: =H35-1 -> 3
A36: B1 | B36: 53 | C36: 111 | D36: 061 | E36: - aardoliewinputten | F36: 100 | G36: 4.1 | H36: 5 | I36: 200 | J36: =FALSE() -> FALSE | K36: 200 | L36: 5 | M36: =FALSE() -> FALSE | N36: =COUNTIF($F$2:$F$560,"<"&F36)+(COUNTIF($F$2:$F$560,F36)+1)/2 -> 415.5 | O36: =COUNTIF($H$2:$H$560,"<"&H36)+(COUNTIF($H$2:$H$560,H36)+1)/2 -> 348.5 | P36: =IF(J36=FALSE(),COUNTIFS($J$2:$J$560,FALSE(),$F$2:$F$560,"<"&F36)+(COUNTIFS($J$2:$J$560,FALSE(),$F$2:$F$560,F36)+1)/2,"") -> 342.5 | Q36: =IF(J36=FALSE(),COUNTIFS($J$2:$J$560,FALSE(),$H$2:$H$560,"<"&H36)+(COUNTIFS($J$2:$J$560,FALSE(),$H$2:$H$560,H36)+1)/2,"") -> 244 | R36: =COUNTIF($L$2:$L$560,"<"&L36)+(COUNTIF($L$2:$L$560,L36)+1)/2 -> 386.5 | S36: =MATCH(F36,Codetabel!$G$2:$G$12,0)-1 -> 4 | T36: =H36-1 -> 4
A37: B1 | B37: 54 | C37: 111 | D37: 062 | E37: - aardgaswinning incl. gasbeh.inst.: < 10.000.000 N m3/d | F37: 30 | G37: 5.1 | H37: 7 | I37: 500 | J37: =FALSE() -> FALSE | K37: 500 | L37: 7 | M37: =FALSE() -> FALSE | N37: =COUNTIF($F$2:$F$560,"<"&F37)+(COUNTIF($F$2:$F$560,F37)+1)/2 -> 257.5 | O37: =COUNTIF($H$2:$H$560,"<"&H37)+(COUNTIF($H$2:$H$560,H37)+1)/2 -> 486.5 | P37: =IF(J37=FALSE(),COUNTIFS($J$2:$J$560,FALSE(),$F$2:$F$560,"<"&F37)+(COUNTIFS($J$2:$J$560,FALSE(),$F$2:$F$560,F37)+1)/2,"") -> 240 | Q37: =IF(J37=FALSE(),COUNTIFS($J$2:$J$560,FALSE(),$H$2:$H$560,"<"&H37)+(COUNTIFS($J$2:$J$560,FALSE(),$H$2:$H$560,H37)+1)/2,"") -> 325.5 | R37: =COUNTIF($L$2:$L$560,"<"&L37)+(COUNTIF($L$2:$L$560,L37)+1)/2 -> 497.5 | S37: =MATCH(F37,Codetabel!$G$2:$G$12,0)-1 -> 2 | T37: =H37-1 -> 6
A38: B1 | B38: 55 | C38: 111 | D38: 062 | E38: - aardgaswinning incl. gasbeh.inst.: >= 10.000.000 N m3/d | F38: 50 | G38: 5.2 | H38: 8 | I38: 700 | J38: =FALSE() -> FALSE | K38: 700 | L38: 8 | M38: =FALSE() -> FALSE | N38: =COUNTIF($F$2:$F$560,"<"&F38)+(COUNTIF($F$2:$F$560,F38)+1)/2 -> 343.5 | O38: =COUNTIF($H$2:$H$560,"<"&H38)+(COUNTIF($H$2:$H$560,H38)+1)/2 -> 520.5 | P38: =IF(J38=FALSE(),COUNTIFS($J$2:$J$560,FALSE(),$F$2:$F$560,"<"&F38)+(COUNTIFS($J$2:$J$560,FALSE(),$F$2:$F$560,F38)+1)/2,"") -> 300.5 | Q38: =IF(J38=FALSE(),COUNTIFS($J$2:$J$560,FALSE(),$H$2:$H$560,"<"&H38)+(COUNTIFS($J$2:$J$560,FALSE(),$H$2:$H$560,H38)+1)/2,"") -> 350.5 | R38: =COUNTIF($L$2:$L$560,"<"&L38)+(COUNTIF($L$2:$L$560,L38)+1)/2 -> 525 | S38: =MATCH(F38,Codetabel!$G$2:$G$12,0)-1 -> 3 | T38: =H38-1 -> 7
A39: B1 | B39: 59 | C39: 1421 | D39: 0812 | E39: - algemeen | F39: 10 | G39: 4.1 | H39: 5 | I39: 200 | J39: =FALSE() -> FALSE | K39: 200 | L39: 5 | M39: =FALSE() -> FALSE | N39: =COUNTIF($F$2:$F$560,"<"&F39)+(COUNTIF($F$2:$F$560,F39)+1)/2 -> 164 | O39: =COUNTIF($H$2:$H$560,"<"&H39)+(COUNTIF($H$2:$H$560,H39)+1)/2 -> 348.5 | P39: =IF(J39=FALSE(),COUNTIFS($J$2:$J$560,FALSE(),$F$2:$F$560,"<"&F39)+(COUNTIFS($J$2:$J$560,FALSE(),$F$2:$F$560,F39)+1)/2,"") -> 161.5 | Q39: =IF(J39=FALSE(),COUNTIFS($J$2:$J$560,FALSE(),$H$2:$H$560,"<"&H39)+(COUNTIFS($J$2:$J$560,FALSE(),$H$2:$H$560,H39)+1)/2,"") -> 244 | R39: =COUNTIF($L$2:$L$560,"<"&L39)+(COUNTIF($L$2:$L$560,L39)+1)/2 -> 386.5 | S39: =MATCH(F39,Codetabel!$G$2:$G$12,0)-1 -> 1 | T39: =H39-1 -> 4
A40: B1 | B40: 60 | C40: 1421 | D40: 0812 | E40: - steenbrekerijen | F40: 10 | G40: 5.2 | H40: 8 | I40: 700 | J40: =FALSE() -> FALSE | K40: 700 | L40: 8 | M40: =FALSE() -> FALSE | N40: =COUNTIF($F$2:$F$560,"<"&F40)+(COUNTIF($F$2:$F$560,F40)+1)/2 -> 164 | O40: =COUNTIF($H$2:$H$560,"<"&H40)+(COUNTIF($H$2:$H$560,H40)+1)/2 -> 520.5 | P40: =IF(J40=FALSE(),COUNTIFS($J$2:$J$560,FALSE(),$F$2:$F$560,"<"&F40)+(COUNTIFS($J$2:$J$560,FALSE(),$F$2:$F$560,F40)+1)/2,"") -> 161.5 | Q40: =IF(J40=FALSE(),COUNTIFS($J$2:$J$560,FALSE(),$H$2:$H$560,"<"&H40)+(COUNTIFS($J$2:$J$560,FALSE(),$H$2:$H$560,H40)+1)/2,"") -> 350.5 | R40: =COUNTIF($L$2:$L$560,"<"&L40)+(COUNTIF($L$2:$L$560,L40)+1)/2 -> 525 | S40: =MATCH(F40,Codetabel!$G$2:$G$12,0)-1 -> 1 | T40: =H40-1 -> 7
A41: B1 | B41: 61 | C41: 144 | D41: 0893 | E41: Zoutwinningbedrijven | F41: 50 | G41: 3.2 | H41: 4 | I41: 100 | J41: =FALSE() -> FALSE | K41: 100 | L41: 4 | M41: =FALSE() -> FALSE | N41: =COUNTIF($F$2:$F$560,"<"&F41)+(COUNTIF($F$2:$F$560,F41)+1)/2 -> 343.5 | O41: =COUNTIF($H$2:$H$560,"<"&H41)+(COUNTIF($H$2:$H$560,H41)+1)/2 -> 266.5 | P41: =IF(J41=FALSE(),COUNTIFS($J$2:$J$560,FALSE(),$F$2:$F$560,"<"&F41)+(COUNTIFS($J$2:$J$560,FALSE(),$F$2:$F$560,F41)+1)/2,"") -> 300.5 | Q41: =IF(J41=FALSE(),COUNTIFS($J$2:$J$560,FALSE(),$H$2:$H$560,"<"&H41)+(COUNTIFS($J$2:$J$560,FALSE(),$H$2:$H$560,H41)+1)/2,"") -> 193.5 | R41: =COUNTIF($L$2:$L$560,"<"&L41)+(COUNTIF($L$2:$L$560,L41)+1)/2 -> 305 | S41: =MATCH(F41,Codetabel!$G$2:$G$12,0)-1 -> 3 | T41: =H41-1 -> 3
...

Sheet Data_B2
A1: Source | B1: Source row | C1: SBI (old) | D1: SBI-2008 | E1: Omschrijving | F1: Geur (m) | G1: Categorie | H1: Category rank | I1: Max distance (m) | J1: Geur decisive | K1: Max other distances (m) | L1: Category rank excl. geur | M1: In both B1 and B2 | N1: Midrank geur | O1: Midrank category | P1: Midrank geur (not decisive) | Q1: Midrank category (not decisive) | R1: Midrank category excl. geur | S1: Geur step index (0-10) | T1: Category step index (0-9)
A2: B2 | B2: 5 | C2: 151 | D2: 101, 102 | E2: - slachterijen en pluimveeslachterijen | F2: 100 | G2: 3.2 | H2: 4 | I2: 100 | J2: =TRUE() -> TRUE | K2: 100 | L2: 4 | M2: =TRUE() -> TRUE | N2: =COUNTIF($F$2:$F$316,"<"&F2)+(COUNTIF($F$2:$F$316,F2)+1)/2 -> 222.5 | O2: =COUNTIF($H$2:$H$316,"<"&H2)+(COUNTIF($H$2:$H$316,H2)+1)/2 -> 140 | P2: =IF(J2=FALSE(),COUNTIFS($J$2:$J$316,FALSE(),$F$2:$F$316,"<"&F2)+(COUNTIFS($J$2:$J$316,FALSE(),$F$2:$F$316,F2)+1)/2,"") | Q2: =IF(J2=FALSE(),COUNTIFS($J$2:$J$316,FALSE(),$H$2:$H$316,"<"&H2)+(COUNTIFS($J$2:$J$316,FALSE(),$H$2:$H$316,H2)+1)/2,"") | R2: =COUNTIF($L$2:$L$316,"<"&L2)+(COUNTIF($L$2:$L$316,L2)+1)/2 -> 166 | S2: =MATCH(F2,Codetabel!$G$2:$G$12,0)-1 -> 4 | T2: =H2-1 -> 3
A3: B2 | B3: 6 | C3: 151 | D3: 101 | E3: - bewerkingsinrichting van darmen en vleesafval | F3: 300 | G3: 4.2 | H3: 6 | I3: 300 | J3: =TRUE() -> TRUE | K3: 100 | L3: 4 | M3: =TRUE() -> TRUE | N3: =COUNTIF($F$2:$F$316,"<"&F3)+(COUNTIF($F$2:$F$316,F3)+1)/2 -> 294.5 | O3: =COUNTIF($H$2:$H$316,"<"&H3)+(COUNTIF($H$2:$H$316,H3)+1)/2 -> 271 | P3: =IF(J3=FALSE(),COUNTIFS($J$2:$J$316,FALSE(),$F$2:$F$316,"<"&F3)+(COUNTIFS($J$2:$J$316,FALSE(),$F$2:$F$316,F3)+1)/2,"") | Q3: =IF(J3=FALSE(),COUNTIFS($J$2:$J$316,FALSE(),$H$2:$H$316,"<"&H3)+(COUNTIFS($J$2:$J$316,FALSE(),$H$2:$H$316,H3)+1)/2,"") | R3: =COUNTIF($L$2:$L$316,"<"&L3)+(COUNTIF($L$2:$L$316,L3)+1)/2 -> 166 | S3: =MATCH(F3,Codetabel!$G$2:$G$12,0)-1 -> 6 | T3: =H3-1 -> 5
A4: B2 | B4: 7 | C4: 151 | D4: 101 | E4: - vleeswaren- en vleesconservenfabrieken: p.o. > 1000 m² | F4: 100 | G4: 3.2 | H4: 4 | I4: 100 | J4: =TRUE() -> TRUE | K4: 100 | L4: 4 | M4: =TRUE() -> TRUE | N4: =COUNTIF($F$2:$F$316,"<"&F4)+(COUNTIF($F$2:$F$316,F4)+1)/2 -> 222.5 | O4: =COUNTIF($H$2:$H$316,"<"&H4)+(COUNTIF($H$2:$H$316,H4)+1)/2 -> 140 | P4: =IF(J4=FALSE(),COUNTIFS($J$2:$J$316,FALSE(),$F$2:$F$316,"<"&F4)+(COUNTIFS($J$2:$J$316,FALSE(),$F$2:$F$316,F4)+1)/2,"") | Q4: =IF(J4=FALSE(),COUNTIFS($J$2:$J$316,FALSE(),$H$2:$H$316,"<"&H4)+(COUNTIFS($J$2:$J$316,FALSE(),$H$2:$H$316,H4)+1)/2,"") | R4: =COUNTIF($L$2:$L$316,"<"&L4)+(COUNTIF($L$2:$L$316,L4)+1)/2 -> 166 | S4: =MATCH(F4,Codetabel!$G$2:$G$12,0)-1 -> 4 | T4: =H4-1 -> 3
A5: B2 | B5: 8 | C5: 151 | D5: 101 | E5: - vleeswaren- en vleesconservenfabrieken: p.o. <= 1000 m² | F5: 50 | G5: 3.1 | H5: 3 | I5: 50 | J5: =TRUE() -> TRUE | K5: 50 | L5: 3 | M5: =TRUE() -> TRUE | N5: =COUNTIF($F$2:$F$316,"<"&F5)+(COUNTIF($F$2:$F$316,F5)+1)/2 -> 175.5 | O5: =COUNTIF($H$2:$H$316,"<"&H5)+(COUNTIF($H$2:$H$316,H5)+1)/2 -> 68 | P5: =IF(J5=FALSE(),COUNTIFS($J$2:$J$316,FALSE(),$F$2:$F$316,"<"&F5)+(COUNTIFS($J$2:$J$316,FALSE(),$F$2:$F$316,F5)+1)/2,"") | Q5: =IF(J5=FALSE(),COUNTIFS($J$2:$J$316,FALSE(),$H$2:$H$316,"<"&H5)+(COUNTIFS($J$2:$J$316,FALSE(),$H$2:$H$316,H5)+1)/2,"") | R5: =COUNTIF($L$2:$L$316,"<"&L5)+(COUNTIF($L$2:$L$316,L5)+1)/2 -> 84.5 | S5: =MATCH(F5,Codetabel!$G$2:$G$12,0)-1 -> 3 | T5: =H5-1 -> 2
A6: B2 | B6: 9 | C6: 151 | D6: 101 | E6: - vleeswaren- en vleesconservenfabrieken: p.o. <= 200 m² | F6: 30 | G6: 3.1 | H6: 3 | I6: 50 | J6: =FALSE() -> FALSE | K6: 50 | L6: 3 | M6: =TRUE() -> TRUE | N6: =COUNTIF($F$2:$F$316,"<"&F6)+(COUNTIF($F$2:$F$316,F6)+1)/2 -> 119.5 | O6: =COUNTIF($H$2:$H$316,"<"&H6)+(COUNTIF($H$2:$H$316,H6)+1)/2 -> 68 | P6: =IF(J6=FALSE(),COUNTIFS($J$2:$J$316,FALSE(),$F$2:$F$316,"<"&F6)+(COUNTIFS($J$2:$J$316,FALSE(),$F$2:$F$316,F6)+1)/2,"") -> 115 | Q6: =IF(J6=FALSE(),COUNTIFS($J$2:$J$316,FALSE(),$H$2:$H$316,"<"&H6)+(COUNTIFS($J$2:$J$316,FALSE(),$H$2:$H$316,H6)+1)/2,"") -> 48.5 | R6: =COUNTIF($L$2:$L$316,"<"&L6)+(COUNTIF($L$2:$L$316,L6)+1)/2 -> 84.5 | S6: =MATCH(F6,Codetabel!$G$2:$G$12,0)-1 -> 2 | T6: =H6-1 -> 2
A7: B2 | B7: 10 | C7: 151 | D7: 101, 102 | E7: - loonslachterijen | F7: 50 | G7: 3.1 | H7: 3 | I7: 50 | J7: =TRUE() -> TRUE | K7: 50 | L7: 3 | M7: =TRUE() -> TRUE | N7: =COUNTIF($F$2:$F$316,"<"&F7)+(COUNTIF($F$2:$F$316,F7)+1)/2 -> 175.5 | O7: =COUNTIF($H$2:$H$316,"<"&H7)+(COUNTIF($H$2:$H$316,H7)+1)/2 -> 68 | P7: =IF(J7=FALSE(),COUNTIFS($J$2:$J$316,FALSE(),$F$2:$F$316,"<"&F7)+(COUNTIFS($J$2:$J$316,FALSE(),$F$2:$F$316,F7)+1)/2,"") | Q7: =IF(J7=FALSE(),COUNTIFS($J$2:$J$316,FALSE(),$H$2:$H$316,"<"&H7)+(COUNTIFS($J$2:$J$316,FALSE(),$H$2:$H$316,H7)+1)/2,"") | R7: =COUNTIF($L$2:$L$316,"<"&L7)+(COUNTIF($L$2:$L$316,L7)+1)/2 -> 84.5 | S7: =MATCH(F7,Codetabel!$G$2:$G$12,0)-1 -> 3 | T7: =H7-1 -> 2
A8: B2 | B8: 11 | C8: 151 | D8: 108 | E8: - vervaardiging van snacks en vervaardiging van kant-en-klaar-maaltijden met p.o. < 2.000 m² | F8: 50 | G8: 3.1 | H8: 3 | I8: 50 | J8: =TRUE() -> TRUE | K8: 50 | L8: 3 | M8: =TRUE() -> TRUE | N8: =COUNTIF($F$2:$F$316,"<"&F8)+(COUNTIF($F$2:$F$316,F8)+1)/2 -> 175.5 | O8: =COUNTIF($H$2:$H$316,"<"&H8)+(COUNTIF($H$2:$H$316,H8)+1)/2 -> 68 | P8: =IF(J8=FALSE(),COUNTIFS($J$2:$J$316,FALSE(),$F$2:$F$316,"<"&F8)+(COUNTIFS($J$2:$J$316,FALSE(),$F$2:$F$316,F8)+1)/2,"") | Q8: =IF(J8=FALSE(),COUNTIFS($J$2:$J$316,FALSE(),$H$2:$H$316,"<"&H8)+(COUNTIFS($J$2:$J$316,FALSE(),$H$2:$H$316,H8)+1)/2,"") | R8: =COUNTIF($L$2:$L$316,"<"&L8)+(COUNTIF($L$2:$L$316,L8)+1)/2 -> 84.5 | S8: =MATCH(F8,Codetabel!$G$2:$G$12,0)-1 -> 3 | T8: =H8-1 -> 2
A9: B2 | B9: 13 | C9: 152 | D9: 102 | E9: - conserveren | F9: 200 | G9: 4.1 | H9: 5 | I9: 200 | J9: =TRUE() -> TRUE | K9: 100 | L9: 4 | M9: =TRUE() -> TRUE | N9: =COUNTIF($F$2:$F$316,"<"&F9)+(COUNTIF($F$2:$F$316,F9)+1)/2 -> 259.5 | O9: =COUNTIF($H$2:$H$316,"<"&H9)+(COUNTIF($H$2:$H$316,H9)+1)/2 -> 207 | P9: =IF(J9=FALSE(),COUNTIFS($J$2:$J$316,FALSE(),$F$2:$F$316,"<"&F9)+(COUNTIFS($J$2:$J$316,FALSE(),$F$2:$F$316,F9)+1)/2,"") | Q9: =IF(J9=FALSE(),COUNTIFS($J$2:$J$316,FALSE(),$H$2:$H$316,"<"&H9)+(COUNTIFS($J$2:$J$316,FALSE(),$H$2:$H$316,H9)+1)/2,"") | R9: =COUNTIF($L$2:$L$316,"<"&L9)+(COUNTIF($L$2:$L$316,L9)+1)/2 -> 166 | S9: =MATCH(F9,Codetabel!$G$2:$G$12,0)-1 -> 5 | T9: =H9-1 -> 4
A10: B2 | B10: 14 | C10: 152 | D10: 102 | E10: - roken | F10: 300 | G10: 4.2 | H10: 6 | I10: 300 | J10: =TRUE() -> TRUE | K10: 50 | L10: 3 | M10: =TRUE() -> TRUE | N10: =COUNTIF($F$2:$F$316,"<"&F10)+(COUNTIF($F$2:$F$316,F10)+1)/2 -> 294.5 | O10: =COUNTIF($H$2:$H$316,"<"&H10)+(COUNTIF($H$2:$H$316,H10)+1)/2 -> 271 | P10: =IF(J10=FALSE(),COUNTIFS($J$2:$J$316,FALSE(),$F$2:$F$316,"<"&F10)+(COUNTIFS($J$2:$J$316,FALSE(),$F$2:$F$316,F10)+1)/2,"") | Q10: =IF(J10=FALSE(),COUNTIFS($J$2:$J$316,FALSE(),$H$2:$H$316,"<"&H10)+(COUNTIFS($J$2:$J$316,FALSE(),$H$2:$H$316,H10)+1)/2,"") | R10: =COUNTIF($L$2:$L$316,"<"&L10)+(COUNTIF($L$2:$L$316,L10)+1)/2 -> 84.5 | S10: =MATCH(F10,Codetabel!$G$2:$G$12,0)-1 -> 6 | T10: =H10-1 -> 5
A11: B2 | B11: 15 | C11: 152 | D11: 102 | E11: - verwerken anderszins: p.o.> 1000 m² | F11: 300 | G11: 4.2 | H11: 6 | I11: 300 | J11: =TRUE() -> TRUE | K11: 50 | L11: 3 | M11: =TRUE() -> TRUE | N11: =COUNTIF($F$2:$F$316,"<"&F11)+(COUNTIF($F$2:$F$316,F11)+1)/2 -> 294.5 | O11: =COUNTIF($H$2:$H$316,"<"&H11)+(COUNTIF($H$2:$H$316,H11)+1)/2 -> 271 | P11: =IF(J11=FALSE(),COUNTIFS($J$2:$J$316,FALSE(),$F$2:$F$316,"<"&F11)+(COUNTIFS($J$2:$J$316,FALSE(),$F$2:$F$316,F11)+1)/2,"") | Q11: =IF(J11=FALSE(),COUNTIFS($J$2:$J$316,FALSE(),$H$2:$H$316,"<"&H11)+(COUNTIFS($J$2:$J$316,FALSE(),$H$2:$H$316,H11)+1)/2,"") | R11: =COUNTIF($L$2:$L$316,"<"&L11)+(COUNTIF($L$2:$L$316,L11)+1)/2 -> 84.5 | S11: =MATCH(F11,Codetabel!$G$2:$G$12,0)-1 -> 6 | T11: =H11-1 -> 5
A12: B2 | B12: 16 | C12: 152 | D12: 102 | E12: - verwerken anderszins: p.o. <= 1000 m² | F12: 100 | G12: 3.2 | H12: 4 | I12: 100 | J12: =TRUE() -> TRUE | K12: 50 | L12: 3 | M12: =TRUE() -> TRUE | N12: =COUNTIF($F$2:$F$316,"<"&F12)+(COUNTIF($F$2:$F$316,F12)+1)/2 -> 222.5 | O12: =COUNTIF($H$2:$H$316,"<"&H12)+(COUNTIF($H$2:$H$316,H12)+1)/2 -> 140 | P12: =IF(J12=FALSE(),COUNTIFS($J$2:$J$316,FALSE(),$F$2:$F$316,"<"&F12)+(COUNTIFS($J$2:$J$316,FALSE(),$F$2:$F$316,F12)+1)/2,"") | Q12: =IF(J12=FALSE(),COUNTIFS($J$2:$J$316,FALSE(),$H$2:$H$316,"<"&H12)+(COUNTIFS($J$2:$J$316,FALSE(),$H$2:$H$316,H12)+1)/2,"") | R12: =COUNTIF($L$2:$L$316,"<"&L12)+(COUNTIF($L$2:$L$316,L12)+1)/2 -> 84.5 | S12: =MATCH(F12,Codetabel!$G$2:$G$12,0)-1 -> 4 | T12: =H12-1 -> 3
A13: B2 | B13: 17 | C13: 152 | D13: 102 | E13: - verwerken anderszins: p.o. <= 300 m² | F13: 50 | G13: 3.1 | H13: 3 | I13: 50 | J13: =TRUE() -> TRUE | K13: 30 | L13: 2 | M13: =TRUE() -> TRUE | N13: =COUNTIF($F$2:$F$316,"<"&F13)+(COUNTIF($F$2:$F$316,F13)+1)/2 -> 175.5 | O13: =COUNTIF($H$2:$H$316,"<"&H13)+(COUNTIF($H$2:$H$316,H13)+1)/2 -> 68 | P13: =IF(J13=FALSE(),COUNTIFS($J$2:$J$316,FALSE(),$F$2:$F$316,"<"&F13)+(COUNTIFS($J$2:$J$316,FALSE(),$F$2:$F$316,F13)+1)/2,"") | Q13: =IF(J13=FALSE(),COUNTIFS($J$2:$J$316,FALSE(),$H$2:$H$316,"<"&H13)+(COUNTIFS($J$2:$J$316,FALSE(),$H$2:$H$316,H13)+1)/2,"") | R13: =COUNTIF($L$2:$L$316,"<"&L13)+(COUNTIF($L$2:$L$316,L13)+1)/2 -> 27 | S13: =MATCH(F13,Codetabel!$G$2:$G$12,0)-1 -> 3 | T13: =H13-1 -> 2
A14: B2 | B14: 19 | C14: 1531 | D14: 1031 | E14: - vervaardiging van aardappelproducten | F14: 300 | G14: 4.2 | H14: 6 | I14: 300 | J14: =TRUE() -> TRUE | K14: 200 | L14: 5 | M14: =TRUE() -> TRUE | N14: =COUNTIF($F$2:$F$316,"<"&F14)+(COUNTIF($F$2:$F$316,F14)+1)/2 -> 294.5 | O14: =COUNTIF($H$2:$H$316,"<"&H14)+(COUNTIF($H$2:$H$316,H14)+1)/2 -> 271 | P14: =IF(J14=FALSE(),COUNTIFS($J$2:$J$316,FALSE(),$F$2:$F$316,"<"&F14)+(COUNTIFS($J$2:$J$316,FALSE(),$F$2:$F$316,F14)+1)/2,"") | Q14: =IF(J14=FALSE(),COUNTIFS($J$2:$J$316,FALSE(),$H$2:$H$316,"<"&H14)+(COUNTIFS($J$2:$J$316,FALSE(),$H$2:$H$316,H14)+1)/2,"") | R14: =COUNTIF($L$2:$L$316,"<"&L14)+(COUNTIF($L$2:$L$316,L14)+1)/2 -> 234.5 | S14: =MATCH(F14,Codetabel!$G$2:$G$12,0)-1 -> 6 | T14: =H14-1 -> 5
A15: B2 | B15: 20 | C15: 1531 | D15: 1031 | E15: - vervaardiging van snacks met p.o. < 2.000 m² | F15: 50 | G15: 3.1 | H15: 3 | I15: 50 | J15: =TRUE() -> TRUE | K15: 50 | L15: 3 | M15: =TRUE() -> TRUE | N15: =COUNTIF($F$2:$F$316,"<"&F15)+(COUNTIF($F$2:$F$316,F15)+1)/2 -> 175.5 | O15: =COUNTIF($H$2:$H$316,"<"&H15)+(COUNTIF($H$2:$H$316,H15)+1)/2 -> 68 | P15: =IF(J15=FALSE(),COUNTIFS($J$2:$J$316,FALSE(),$F$2:$F$316,"<"&F15)+(COUNTIFS($J$2:$J$316,FALSE(),$F$2:$F$316,F15)+1)/2,"") | Q15: =IF(J15=FALSE(),COUNTIFS($J$2:$J$316,FALSE(),$H$2:$H$316,"<"&H15)+(COUNTIFS($J$2:$J$316,FALSE(),$H$2:$H$316,H15)+1)/2,"") | R15: =COUNTIF($L$2:$L$316,"<"&L15)+(COUNTIF($L$2:$L$316,L15)+1)/2 -> 84.5 | S15: =MATCH(F15,Codetabel!$G$2:$G$12,0)-1 -> 3 | T15: =H15-1 -> 2
A16: B2 | B16: 22 | C16: 1532, 1533 | D16: 1032, 1039 | E16: - jam | F16: 50 | G16: 3.2 | H16: 4 | I16: 100 | J16: =FALSE() -> FALSE | K16: 100 | L16: 4 | M16: =TRUE() -> TRUE | N16: =COUNTIF($F$2:$F$316,"<"&F16)+(COUNTIF($F$2:$F$316,F16)+1)/2 -> 175.5 | O16: =COUNTIF($H$2:$H$316,"<"&H16)+(COUNTIF($H$2:$H$316,H16)+1)/2 -> 140 | P16: =IF(J16=FALSE(),COUNTIFS($J$2:$J$316,FALSE(),$F$2:$F$316,"<"&F16)+(COUNTIFS($J$2:$J$316,FALSE(),$F$2:$F$316,F16)+1)/2,"") -> 156 | Q16: =IF(J16=FALSE(),COUNTIFS($J$2:$J$316,FALSE(),$H$2:$H$316,"<"&H16)+(COUNTIFS($J$2:$J$316,FALSE(),$H$2:$H$316,H16)+1)/2,"") -> 98 | R16: =COUNTIF($L$2:$L$316,"<"&L16)+(COUNTIF($L$2:$L$316,L16)+1)/2 -> 166 | S16: =MATCH(F16,Codetabel!$G$2:$G$12,0)-1 -> 3 | T16: =H16-1 -> 3
A17: B2 | B17: 23 | C17: 1532, 1533 | D17: 1032, 1039 | E17: - groente algemeen | F17: 50 | G17: 3.2 | H17: 4 | I17: 100 | J17: =FALSE() -> FALSE | K17: 100 | L17: 4 | M17: =TRUE() -> TRUE | N17: =COUNTIF($F$2:$F$316,"<"&F17)+(COUNTIF($F$2:$F$316,F17)+1)/2 -> 175.5 | O17: =COUNTIF($H$2:$H$316,"<"&H17)+(COUNTIF($H$2:$H$316,H17)+1)/2 -> 140 | P17: =IF(J17=FALSE(),COUNTIFS($J$2:$J$316,FALSE(),$F$2:$F$316,"<"&F17)+(COUNTIFS($J$2:$J$316,FALSE(),$F$2:$F$316,F17)+1)/2,"") -> 156 | Q17: =IF(J17=FALSE(),COUNTIFS($J$2:$J$316,FALSE(),$H$2:$H$316,"<"&H17)+(COUNTIFS($J$2:$J$316,FALSE(),$H$2:$H$316,H17)+1)/2,"") -> 98 | R17: =COUNTIF($L$2:$L$316,"<"&L17)+(COUNTIF($L$2:$L$316,L17)+1)/2 -> 166 | S17: =MATCH(F17,Codetabel!$G$2:$G$12,0)-1 -> 3 | T17: =H17-1 -> 3
A18: B2 | B18: 24 | C18: 1532, 1533 | D18: 1032, 1039 | E18: - met koolsoorten | F18: 100 | G18: 3.2 | H18: 4 | I18: 100 | J18: =TRUE() -> TRUE | K18: 100 | L18: 4 | M18: =TRUE() -> TRUE | N18: =COUNTIF($F$2:$F$316,"<"&F18)+(COUNTIF($F$2:$F$316,F18)+1)/2 -> 222.5 | O18: =COUNTIF($H$2:$H$316,"<"&H18)+(COUNTIF($H$2:$H$316,H18)+1)/2 -> 140 | P18: =IF(J18=FALSE(),COUNTIFS($J$2:$J$316,FALSE(),$F$2:$F$316,"<"&F18)+(COUNTIFS($J$2:$J$316,FALSE(),$F$2:$F$316,F18)+1)/2,"") | Q18: =IF(J18=FALSE(),COUNTIFS($J$2:$J$316,FALSE(),$H$2:$H$316,"<"&H18)+(COUNTIFS($J$2:$J$316,FALSE(),$H$2:$H$316,H18)+1)/2,"") | R18: =COUNTIF($L$2:$L$316,"<"&L18)+(COUNTIF($L$2:$L$316,L18)+1)/2 -> 166 | S18: =MATCH(F18,Codetabel!$G$2:$G$12,0)-1 -> 4 | T18: =H18-1 -> 3
A19: B2 | B19: 25 | C19: 1532, 1533 | D19: 1032, 1039 | E19: - met drogerijen | F19: 300 | G19: 4.2 | H19: 6 | I19: 300 | J19: =TRUE() -> TRUE | K19: 200 | L19: 5 | M19: =TRUE() -> TRUE | N19: =COUNTIF($F$2:$F$316,"<"&F19)+(COUNTIF($F$2:$F$316,F19)+1)/2 -> 294.5 | O19: =COUNTIF($H$2:$H$316,"<"&H19)+(COUNTIF($H$2:$H$316,H19)+1)/2 -> 271 | P19: =IF(J19=FALSE(),COUNTIFS($J$2:$J$316,FALSE(),$F$2:$F$316,"<"&F19)+(COUNTIFS($J$2:$J$316,FALSE(),$F$2:$F$316,F19)+1)/2,"") | Q19: =IF(J19=FALSE(),COUNTIFS($J$2:$J$316,FALSE(),$H$2:$H$316,"<"&H19)+(COUNTIFS($J$2:$J$316,FALSE(),$H$2:$H$316,H19)+1)/2,"") | R19: =COUNTIF($L$2:$L$316,"<"&L19)+(COUNTIF($L$2:$L$316,L19)+1)/2 -> 234.5 | S19: =MATCH(F19,Codetabel!$G$2:$G$12,0)-1 -> 6 | T19: =H19-1 -> 5
A20: B2 | B20: 26 | C20: 1532, 1533 | D20: 1032, 1039 | E20: - met uienconservering (zoutinleggerij) | F20: 300 | G20: 4.2 | H20: 6 | I20: 300 | J20: =TRUE() -> TRUE | K20: 100 | L20: 4 | M20: =TRUE() -> TRUE | N20: =COUNTIF($F$2:$F$316,"<"&F20)+(COUNTIF($F$2:$F$316,F20)+1)/2 -> 294.5 | O20: =COUNTIF($H$2:$H$316,"<"&H20)+(COUNTIF($H$2:$H$316,H20)+1)/2 -> 271 | P20: =IF(J20=FALSE(),COUNTIFS($J$2:$J$316,FALSE(),$F$2:$F$316,"<"&F20)+(COUNTIFS($J$2:$J$316,FALSE(),$F$2:$F$316,F20)+1)/2,"") | Q20: =IF(J20=FALSE(),COUNTIFS($J$2:$J$316,FALSE(),$H$2:$H$316,"<"&H20)+(COUNTIFS($J$2:$J$316,FALSE(),$H$2:$H$316,H20)+1)/2,"") | R20: =COUNTIF($L$2:$L$316,"<"&L20)+(COUNTIF($L$2:$L$316,L20)+1)/2 -> 166 | S20: =MATCH(F20,Codetabel!$G$2:$G$12,0)-1 -> 6 | T20: =H20-1 -> 5
A21: B2 | B21: 28 | C21: 1541 | D21: 104101 | E21: - p.c. < 250.000 t/j | F21: 200 | G21: 4.1 | H21: 5 | I21: 200 | J21: =TRUE() -> TRUE | K21: 100 | L21: 4 | M21: =TRUE() -> TRUE | N21: =COUNTIF($F$2:$F$316,"<"&F21)+(COUNTIF($F$2:$F$316,F21)+1)/2 -> 259.5 | O21: =COUNTIF($H$2:$H$316,"<"&H21)+(COUNTIF($H$2:$H$316,H21)+1)/2 -> 207 | P21: =IF(J21=FALSE(),COUNTIFS($J$2:$J$316,FALSE(),$F$2:$F$316,"<"&F21)+(COUNTIFS($J$2:$J$316,FALSE(),$F$2:$F$316,F21)+1)/2,"") | Q21: =IF(J21=FALSE(),COUNTIFS($J$2:$J$316,FALSE(),$H$2:$H$316,"<"&H21)+(COUNTIFS($J$2:$J$316,FALSE(),$H$2:$H$316,H21)+1)/2,"") | R21: =COUNTIF($L$2:$L$316,"<"&L21)+(COUNTIF($L$2:$L$316,L21)+1)/2 -> 166 | S21: =MATCH(F21,Codetabel!$G$2:$G$12,0)-1 -> 5 | T21: =H21-1 -> 4
A22: B2 | B22: 29 | C22: 1541 | D22: 104101 | E22: - p.c. >= 250.000 t/j | F22: 300 | G22: 4.2 | H22: 6 | I22: 300 | J22: =TRUE() -> TRUE | K22: 300 | L22: 6 | M22: =TRUE() -> TRUE | N22: =COUNTIF($F$2:$F$316,"<"&F22)+(COUNTIF($F$2:$F$316,F22)+1)/2 -> 294.5 | O22: =COUNTIF($H$2:$H$316,"<"&H22)+(COUNTIF($H$2:$H$316,H22)+1)/2 -> 271 | P22: =IF(J22=FALSE(),COUNTIFS($J$2:$J$316,FALSE(),$F$2:$F$316,"<"&F22)+(COUNTIFS($J$2:$J$316,FALSE(),$F$2:$F$316,F22)+1)/2,"") | Q22: =IF(J22=FALSE(),COUNTIFS($J$2:$J$316,FALSE(),$H$2:$H$316,"<"&H22)+(COUNTIFS($J$2:$J$316,FALSE(),$H$2:$H$316,H22)+1)/2,"") | R22: =COUNTIF($L$2:$L$316,"<"&L22)+(COUNTIF($L$2:$L$316,L22)+1)/2 -> 283.5 | S22: =MATCH(F22,Codetabel!$G$2:$G$12,0)-1 -> 6 | T22: =H22-1 -> 5
A23: B2 | B23: 31 | C23: 1542 | D23: 104102 | E23: - p.c. < 250.000 t/j | F23: 200 | G23: 4.1 | H23: 5 | I23: 200 | J23: =TRUE() -> TRUE | K23: 100 | L23: 4 | M23: =TRUE() -> TRUE | N23: =COUNTIF($F$2:$F$316,"<"&F23)+(COUNTIF($F$2:$F$316,F23)+1)/2 -> 259.5 | O23: =COUNTIF($H$2:$H$316,"<"&H23)+(COUNTIF($H$2:$H$316,H23)+1)/2 -> 207 | P23: =IF(J23=FALSE(),COUNTIFS($J$2:$J$316,FALSE(),$F$2:$F$316,"<"&F23)+(COUNTIFS($J$2:$J$316,FALSE(),$F$2:$F$316,F23)+1)/2,"") | Q23: =IF(J23=FALSE(),COUNTIFS($J$2:$J$316,FALSE(),$H$2:$H$316,"<"&H23)+(COUNTIFS($J$2:$J$316,FALSE(),$H$2:$H$316,H23)+1)/2,"") | R23: =COUNTIF($L$2:$L$316,"<"&L23)+(COUNTIF($L$2:$L$316,L23)+1)/2 -> 166 | S23: =MATCH(F23,Codetabel!$G$2:$G$12,0)-1 -> 5 | T23: =H23-1 -> 4
A24: B2 | B24: 32 | C24: 1542 | D24: 104102 | E24: - p.c. >= 250.000 t/j | F24: 300 | G24: 4.2 | H24: 6 | I24: 300 | J24: =TRUE() -> TRUE | K24: 300 | L24: 6 | M24: =TRUE() -> TRUE | N24: =COUNTIF($F$2:$F$316,"<"&F24)+(COUNTIF($F$2:$F$316,F24)+1)/2 -> 294.5 | O24: =COUNTIF($H$2:$H$316,"<"&H24)+(COUNTIF($H$2:$H$316,H24)+1)/2 -> 271 | P24: =IF(J24=FALSE(),COUNTIFS($J$2:$J$316,FALSE(),$F$2:$F$316,"<"&F24)+(COUNTIFS($J$2:$J$316,FALSE(),$F$2:$F$316,F24)+1)/2,"") | Q24: =IF(J24=FALSE(),COUNTIFS($J$2:$J$316,FALSE(),$H$2:$H$316,"<"&H24)+(COUNTIFS($J$2:$J$316,FALSE(),$H$2:$H$316,H24)+1)/2,"") | R24: =COUNTIF($L$2:$L$316,"<"&L24)+(COUNTIF($L$2:$L$316,L24)+1)/2 -> 283.5 | S24: =MATCH(F24,Codetabel!$G$2:$G$12,0)-1 -> 6 | T24: =H24-1 -> 5
A25: B2 | B25: 34 | C25: 1543 | D25: 1042 | E25: - p.c. < 250.000 t/j | F25: 100 | G25: 4.1 | H25: 5 | I25: 200 | J25: =FALSE() -> FALSE | K25: 200 | L25: 5 | M25: =TRUE() -> TRUE | N25: =COUNTIF($F$2:$F$316,"<"&F25)+(COUNTIF($F$2:$F$316,F25)+1)/2 -> 222.5 | O25: =COUNTIF($H$2:$H$316,"<"&H25)+(COUNTIF($H$2:$H$316,H25)+1)/2 -> 207 | P25: =IF(J25=FALSE(),COUNTIFS($J$2:$J$316,FALSE(),$F$2:$F$316,"<"&F25)+(COUNTIFS($J$2:$J$316,FALSE(),$F$2:$F$316,F25)+1)/2,"") -> 180.5 | Q25: =IF(J25=FALSE(),COUNTIFS($J$2:$J$316,FALSE(),$H$2:$H$316,"<"&H25)+(COUNTIFS($J$2:$J$316,FALSE(),$H$2:$H$316,H25)+1)/2,"") -> 141 | R25: =COUNTIF($L$2:$L$316,"<"&L25)+(COUNTIF($L$2:$L$316,L25)+1)/2 -> 234.5 | S25: =MATCH(F25,Codetabel!$G$2:$G$12,0)-1 -> 4 | T25: =H25-1 -> 4
A26: B2 | B26: 35 | C26: 1543 | D26: 1042 | E26: - p.c. >= 250.000 t/j | F26: 200 | G26: 4.2 | H26: 6 | I26: 300 | J26: =FALSE() -> FALSE | K26: 300 | L26: 6 | M26: =TRUE() -> TRUE | N26: =COUNTIF($F$2:$F$316,"<"&F26)+(COUNTIF($F$2:$F$316,F26)+1)/2 -> 259.5 | O26: =COUNTIF($H$2:$H$316,"<"&H26)+(COUNTIF($H$2:$H$316,H26)+1)/2 -> 271 | P26: =IF(J26=FALSE(),COUNTIFS($J$2:$J$316,FALSE(),$F$2:$F$316,"<"&F26)+(COUNTIFS($J$2:$J$316,FALSE(),$F$2:$F$316,F26)+1)/2,"") -> 193.5 | Q26: =IF(J26=FALSE(),COUNTIFS($J$2:$J$316,FALSE(),$H$2:$H$316,"<"&H26)+(COUNTIFS($J$2:$J$316,FALSE(),$H$2:$H$316,H26)+1)/2,"") -> 175 | R26: =COUNTIF($L$2:$L$316,"<"&L26)+(COUNTIF($L$2:$L$316,L26)+1)/2 -> 283.5 | S26: =MATCH(F26,Codetabel!$G$2:$G$12,0)-1 -> 5 | T26: =H26-1 -> 5
A27: B2 | B27: 37 | C27: 1551 | D27: 1051 | E27: - melkprodukten fabrieken v.c. < 55.000 t/j | F27: 50 | G27: 3.2 | H27: 4 | I27: 100 | J27: =FALSE() -> FALSE | K27: 100 | L27: 4 | M27: =TRUE() -> TRUE | N27: =COUNTIF($F$2:$F$316,"<"&F27)+(COUNTIF($F$2:$F$316,F27)+1)/2 -> 175.5 | O27: =COUNTIF($H$2:$H$316,"<"&H27)+(COUNTIF($H$2:$H$316,H27)+1)/2 -> 140 | P27: =IF(J27=FALSE(),COUNTIFS($J$2:$J$316,FALSE(),$F$2:$F$316,"<"&F27)+(COUNTIFS($J$2:$J$316,FALSE(),$F$2:$F$316,F27)+1)/2,"") -> 156 | Q27: =IF(J27=FALSE(),COUNTIFS($J$2:$J$316,FALSE(),$H$2:$H$316,"<"&H27)+(COUNTIFS($J$2:$J$316,FALSE(),$H$2:$H$316,H27)+1)/2,"") -> 98 | R27: =COUNTIF($L$2:$L$316,"<"&L27)+(COUNTIF($L$2:$L$316,L27)+1)/2 -> 166 | S27: =MATCH(F27,Codetabel!$G$2:$G$12,0)-1 -> 3 | T27: =H27-1 -> 3
A28: B2 | B28: 38 | C28: 1551 | D28: 1051 | E28: - melkprodukten fabrieken v.c. >= 55.000 t/j | F28: 100 | G28: 4.2 | H28: 6 | I28: 300 | J28: =FALSE() -> FALSE | K28: 300 | L28: 6 | M28: =TRUE() -> TRUE | N28: =COUNTIF($F$2:$F$316,"<"&F28)+(COUNTIF($F$2:$F$316,F28)+1)/2 -> 222.5 | O28: =COUNTIF($H$2:$H$316,"<"&H28)+(COUNTIF($H$2:$H$316,H28)+1)/2 -> 271 | P28: =IF(J28=FALSE(),COUNTIFS($J$2:$J$316,FALSE(),$F$2:$F$316,"<"&F28)+(COUNTIFS($J$2:$J$316,FALSE(),$F$2:$F$316,F28)+1)/2,"") -> 180.5 | Q28: =IF(J28=FALSE(),COUNTIFS($J$2:$J$316,FALSE(),$H$2:$H$316,"<"&H28)+(COUNTIFS($J$2:$J$316,FALSE(),$H$2:$H$316,H28)+1)/2,"") -> 175 | R28: =COUNTIF($L$2:$L$316,"<"&L28)+(COUNTIF($L$2:$L$316,L28)+1)/2 -> 283.5 | S28: =MATCH(F28,Codetabel!$G$2:$G$12,0)-1 -> 4 | T28: =H28-1 -> 5
A29: B2 | B29: 39 | C29: 1551 | D29: 1051 | E29: - overige zuivelprodukten fabrieken | F29: 50 | G29: 4.2 | H29: 6 | I29: 300 | J29: =FALSE() -> FALSE | K29: 300 | L29: 6 | M29: =TRUE() -> TRUE | N29: =COUNTIF($F$2:$F$316,"<"&F29)+(COUNTIF($F$2:$F$316,F29)+1)/2 -> 175.5 | O29: =COUNTIF($H$2:$H$316,"<"&H29)+(COUNTIF($H$2:$H$316,H29)+1)/2 -> 271 | P29: =IF(J29=FALSE(),COUNTIFS($J$2:$J$316,FALSE(),$F$2:$F$316,"<"&F29)+(COUNTIFS($J$2:$J$316,FALSE(),$F$2:$F$316,F29)+1)/2,"") -> 156 | Q29: =IF(J29=FALSE(),COUNTIFS($J$2:$J$316,FALSE(),$H$2:$H$316,"<"&H29)+(COUNTIFS($J$2:$J$316,FALSE(),$H$2:$H$316,H29)+1)/2,"") -> 175 | R29: =COUNTIF($L$2:$L$316,"<"&L29)+(COUNTIF($L$2:$L$316,L29)+1)/2 -> 283.5 | S29: =MATCH(F29,Codetabel!$G$2:$G$12,0)-1 -> 3 | T29: =H29-1 -> 5
